Workbook

Sheet Resumen
A2: RESUMEN DE CÁLCULOS
A6: Ítem | B6: Resultado | C6: Unidad | D6: Valor | E6: Desarrollo
A7: 01 | B7: Usuarios potenciales | C7: ud | D7: =Demanda!G27 -> 353 | E7: Proyección geométrica por localidad
A8: 02 | B8: Demanda máxima | C8: kW | D8: =Demanda!G21 -> 171.486 | E8: Doméstica + alumbrado + servicios
A9: 03 | B9: Potencia aparente de carga | C9: kVA | D9: =Demanda!G25 -> 190.54 | E9: P / FP
A11: 04 | B11: Longitud eléctrica por fase | C11: m | D11: =Electrico!B7 -> 6758.1203 | E11: Catenaria EDS de 110 vanos
A12: 05 | B12: Resistencia de fase | C12: Ω | D12: =Electrico!B10 -> 5.4325691 | E12: Temperatura de cálculo 75 °C
A13: 06 | B13: Reactancia de fase | C13: Ω | D13: =Electrico!B11 -> 3.0914667 | E13: Disposición horizontal 1.2 / 1.2 / 2.4 m
A15: 07 | B15: Corriente de la línea | C15: A | D15: =Electrico!B22 -> 11.35633 | E15: Barrido radial con ambos transformadores
A16: 08 | B16: Tensión BT de llegada | C16: V | D16: =Electrico!B21 -> 371.06663 | E16: Generador + T1 + línea + T2
A17: 09 | B17: Pérdida activa de la línea | C17: kW | D17: =Electrico!B23 -> 2.101854 | E17: 3 I² R
A18: 10 | B18: Generación requerida | C18: kW | D18: =Electrico!B24 -> 183.32615 | E18: Carga + pérdidas + auxiliares
A19: 11 | B19: Potencia aparente del generador | C19: kVA | D19: =Electrico!B26 -> 212.4805 | E19: Potencias activa y reactiva de fuente
A21: 12 | B21: Ik3 subtransitoria MT de llegada | C21: A | D21: =Cortocircuito!H8 -> 53.384805 | E21: Impedancias de fuente, T1 y línea
A22: 13 | B22: Ik3 subtransitoria BT de llegada | C22: A | D22: =Cortocircuito!H9 -> 1149.8399 | E22: Incluye T2 y relación MT/BT
A24: 14 | B24: D/C máximo de flexión tipo | C24: - | D24: =MAX(Mecanica!F7:F117) -> 0.59769994 | E24: Momentos de la envolvente del modelo
A25: 15 | B25: Apoyos con carga ascendente | C25: ud | D25: =COUNTIFS(Mecanica!G7:G117,"<0") -> 46 | E25: Vertical mínima negativa
A26: 16 | B26: Rotura mínima de retenida | C26: kN | D26: =Parametros!E16 -> 60 | E26: Especificación de suministro
A28: 17 | B28: Margen de potencia nominal | C28: kW | D28: =Electrico!B27 -> 16.673849 | E28: Referencia de 200 kW menos necesidad
A29: 18 | B29: Margen con 25 kW para Limbani | C29: kW | D29: =D28-25 -> -8.3261509 | E29: Balance de oferta compartida
B32: Caso: 10 kV, fuente equivalente 1.05 pu.
B33: Geometría de gabinete y datos tipo de equipos.

Sheet Demanda
A2: CÁLCULO DE DEMANDA
A6: Localidad | B6: Viviendas 2017 | C6: Años | D6: Usuarios 2026 | E6: kW/usuario | F6: Simultaneidad | G6: Demanda (kW)
A7: Huancasayani Centro | B7: 95 | C7: =Parametros!$E$42-Parametros!$E$43 -> 9 | D7: =ROUNDUP(B7*(1+Parametros!$E$44)^C7,0) -> 104 | E7: 0.6 | F7: =Parametros!$E$45 -> 0.8 | G7: =D7*E7*F7 -> 49.92
A8: Huancasayani Bellavista | B8: 140 | C8: =Parametros!$E$42-Parametros!$E$43 -> 9 | D8: =ROUNDUP(B8*(1+Parametros!$E$44)^C8,0) -> 154 | E8: 0.6 | F8: =Parametros!$E$45 -> 0.8 | G8: =D8*E8*F8 -> 73.92
A9: Huancasayani Lince | B9: 86 | C9: =Parametros!$E$42-Parametros!$E$43 -> 9 | D9: =ROUNDUP(B9*(1+Parametros!$E$44)^C9,0) -> 95 | E9: 0.4 | F9: =Parametros!$E$45 -> 0.8 | G9: =D9*E9*F9 -> 30.4
A11: Demanda doméstica | G11: =SUM(G7:G9) -> 154.24
A13: Alumbrado público | G13: =Parametros!$E$46*Parametros!$E$47 -> 3.246
A15: Salud | G15: 3
A16: Educación y comunicaciones | G16: 3
A17: Agua y bombeo | G17: 3
A18: Comercio y talleres | G18: 4
A19: Servicios comunales | G19: 1
A21: DEMANDA MÁXIMA | G21: =G11+G13+SUM(G15:G19) -> 171.486
A23: Factor de potencia | G23: =Parametros!$E$36 -> 0.9
A24: Potencia reactiva (kvar) | G24: =G21*TAN(ACOS(G23)) -> 83.05446
A25: Potencia aparente (kVA) | G25: =G21/G23 -> 190.54
A27: Usuarios potenciales | G27: =SUM(D7:D9) -> 353

Sheet Electrico
A2: PARÁMETROS ELÉCTRICOS Y RESULTADOS
A6: Magnitud | B6: Valor | C6: Unidad | D6: Expresión
A7: Longitud eléctrica por fase | B7: =SUM(Vanos!$M$7:$M$116) -> 6758.1203 | C7: m | D7: Suma de longitudes EDS
A8: Distancia media geométrica | B8: =(Parametros!E19*Parametros!E20*Parametros!E21)^(1/3) -> 1.5119053 | C8: m | D8: DMG = (Dab × Dbc × Dca)^(1/3)
A9: Radio medio geométrico | B9: =0.7788*Parametros!E25/2 -> 0.0035046 | C9: m | D9: GMR = 0.7788 × d / 2
A10: Resistencia de fase | B10: =Parametros!E22*(1+Parametros!E23*(Parametros!E24-20))*B7/1000 -> 5.4325691 | C10: Ω | D10: R = R20 [1 + αR (T − 20)] L
A11: Reactancia de fase | B11: =2*PI()*Parametros!E26*0.0002*LN(B8/B9)*B7/1000 -> 3.0914667 | C11: Ω | D11: X = 2πf × 2·10^-4 ln(DMG/GMR) L
A13: Resistencia del transformador | B13: =Parametros!E32/Parametros!E30 -> 0.0124 | C13: pu | D13: rTX = Pcu / Sn
A14: Reactancia del transformador | B14: =SQRT(Parametros!E31^2-B13^2) -> 0.058704685 | C14: pu | D14: xTX = √(uk² − rTX²)
A15: Impedancia base MT | B15: =(Parametros!E27*1000)^2/(Parametros!E30*1000) -> 400 | C15: Ω | D15: Zb = Vn² / Sn
A16: Resistencia TX referida a MT | B16: =B13*B15 -> 4.96 | C16: Ω | D16: RTX = rTX × Zb
A17: Reactancia TX referida a MT | B17: =B14*B15 -> 23.481874 | C17: Ω | D17: XTX = xTX × Zb
A18: Tensión de fuente por fase | B18: =Parametros!E27*1000*Parametros!E28/SQRT(3) -> 6062.1778 | C18: V | D18: Vfuente = Vn × t / √3
A21: Tensión BT de llegada | B21: =Flujo!N66 -> 371.06663 | C21: V | D21: √3 |V3| × Vbt/Vn
A22: Corriente en la línea | B22: =Flujo!O66 -> 11.35633 | C22: A | D22: |I2|
A23: Pérdida activa de línea | B23: =Flujo!P66 -> 2.101854 | C23: kW | D23: 3 |I2|² R
A24: Potencia activa de generación | B24: =3*B18*Flujo!H66/1000+Parametros!E35 -> 183.32615 | C24: kW | D24: Potencia de fuente más auxiliares
A25: Potencia reactiva de generación | B25: =-3*B18*Flujo!I66/1000 -> 107.422 | C25: kvar | D25: −3 Vfuente Im(I1)
A26: Potencia aparente del generador | B26: =SQRT(B24^2+B25^2) -> 212.4805 | C26: kVA | D26: √(Pg² + Qg²)
A27: Margen frente a 200 kW | B27: =Parametros!E41-B24 -> 16.673849 | C27: kW | D27: Pg nominal − Pg requerida
A28: Carga relativa del generador | B28: =B26/Parametros!E30 -> 0.849922 | C28: pu | D28: Sg / Sn
A30: Tensión MT de salida | B30: =SQRT(Flujo!B66^2+Flujo!C66^2)*SQRT(3)/1000 -> 10.181478 | C30: kV | D30: √3 |V1|
A31: Tensión MT de llegada | B31: =SQRT(Flujo!D66^2+Flujo!E66^2)*SQRT(3)/1000 -> 10.058553 | C31: kV | D31: √3 |V2|
A32: Caída de la línea | B32: =(B30-B31)/B30 -> 0.012073367 | C32: pu | D32: (V1 − V2) / V1
A33: Residuo de iteración de tensión | B33: =Flujo!Q66 -> 0 | C33: V | D33: Diferencia máxima de dos iteraciones

Sheet Flujo
A2: BALANCE RADIAL POR BARRIDO ITERATIVO
A6: Iteración | B6: Re V1 (V) | C6: Im V1 (V) | D6: Re V2 (V) | E6: Im V2 (V) | F6: Re V3 (V) | G6: Im V3 (V) | H6: Re I1 (A) | I6: Im I1 (A) | J6: Re I2 (A) | K6: Im I2 (A) | L6: Re I3 (A) | M6: Im I3 (A) | N6: BT final (V) | O6: I línea (A) | P6: P línea (kW) | Q6: ΔV iter. (V)
A7: 0 | B7: =Electrico!$B$18 -> 6062.1778 | C7: =0 -> 0 | D7: =Electrico!$B$18 -> 6062.1778 | E7: =0 -> 0 | F7: =Electrico!$B$18 -> 6062.1778 | G7: =0 -> 0 | H7: =J7+(Parametros!$E$33*1000*B7+Parametros!$E$34*1000*C7)/(3*(B7^2+C7^2)) -> 9.4787718 | I7: =K7+(Parametros!$E$33*1000*C7-Parametros!$E$34*1000*B7)/(3*(B7^2+C7^2)) -> -4.8417397 | J7: =L7+(Parametros!$E$33*1000*D7+Parametros!$E$34*1000*E7)/(3*(D7^2+E7^2)) -> 9.4540282 | K7: =M7+(Parametros!$E$33*1000*E7-Parametros!$E$34*1000*D7)/(3*(D7^2+E7^2)) -> -4.7042753 | L7: =(Demanda!$G$21*1000*F7+Demanda!$G$24*1000*G7)/(3*(F7^2+G7^2)) -> 9.4292846 | M7: =(Demanda!$G$21*1000*G7-Demanda!$G$24*1000*F7)/(3*(F7^2+G7^2)) -> -4.566811 | N7: =SQRT(F7^2+G7^2)*SQRT(3)*Parametros!$E$29/(Parametros!$E$27*1000) -> 399 | O7: =SQRT(J7^2+K7^2) -> 10.559775 | P7: =3*O7^2*Electrico!$B$10/1000 -> 1.8173387 | Q7: =0 -> 0
A8: 1 | B8: =0.7*(Electrico!$B$18-Electrico!$B$16*H7+Electrico!$B$17*I7)+0.3*B7 -> 5949.6823 | C8: =0.7*(-Electrico!$B$16*I7-Electrico!$B$17*H7)+0.3*C7 -> -138.99501 | D8: =0.7*(Electrico!$B$18-Electrico!$B$16*H7+Electrico!$B$17*I7-Electrico!$B$10*J7+Electrico!$B$11*K7)+0.3*D7 -> 5903.5504 | E8: =0.7*(-Electrico!$B$16*I7-Electrico!$B$17*H7-Electrico!$B$10*K7-Electrico!$B$11*J7)+0.3*E7 -> -141.56436 | F8: =0.7*(Electrico!$B$18-Electrico!$B$16*H7+Electrico!$B$17*I7-Electrico!$B$10*J7+Electrico!$B$11*K7-Electrico!$B$16*L7+Electrico!$B$17*M7)+0.3*F7 -> 5795.7458 | G8: =0.7*(-Electrico!$B$16*I7-Electrico!$B$17*H7-Electrico!$B$10*K7-Electrico!$B$11*J7-Electrico!$B$16*M7-Electrico!$B$17*L7)+0.3*G7 -> -280.70049 | H8: =J8+(Parametros!$E$33*1000*B8+Parametros!$E$34*1000*C8)/(3*(B8^2+C8^2)) -> 9.652802 | I8: =K8+(Parametros!$E$33*1000*C8-Parametros!$E$34*1000*B8)/(3*(B8^2+C8^2)) -> -5.5243881 | J8: =L8+(Parametros!$E$33*1000*D8+Parametros!$E$34*1000*E8)/(3*(D8^2+E8^2)) -> 9.6308747 | K8: =M8+(Parametros!$E$33*1000*E8-Parametros!$E$34*1000*D8)/(3*(D8^2+E8^2)) -> -5.3838123 | L8: =(Demanda!$G$21*1000*F8+Demanda!$G$24*1000*G8)/(3*(F8^2+G8^2)) -> 9.6088638 | M8: =(Demanda!$G$21*1000*G8-Demanda!$G$24*1000*F8)/(3*(F8^2+G8^2)) -> -5.2421265 | N8: =SQRT(F8^2+G8^2)*SQRT(3)*Parametros!$E$29/(Parametros!$E$27*1000) -> 381.91113 | O8: =SQRT(J8^2+K8^2) -> 11.033548 | P8: =3*O8^2*Electrico!$B$10/1000 -> 1.9840696 | Q8: =MAX(ABS(B8-B7),ABS(C8-C7),ABS(D8-D7),ABS(E8-E7),ABS(F8-F7),ABS(G8-G7)) -> 280.70049
A9: 2 | B9: =0.7*(Electrico!$B$18-Electrico!$B$16*H8+Electrico!$B$17*I8)+0.3*B8 -> 5904.1086 | C9: =0.7*(-Electrico!$B$16*I8-Electrico!$B$17*H8)+0.3*C8 -> -181.18394 | D9: =0.7*(Electrico!$B$18-Electrico!$B$16*H8+Electrico!$B$17*I8-Electrico!$B$10*J8+Electrico!$B$11*K8)+0.3*D8 -> 5841.994 | E9: =0.7*(-Electrico!$B$16*I8-Electrico!$B$17*H8-Electrico!$B$10*K8-Electrico!$B$11*J8)+0.3*E8 -> -182.32267 | F9: =0.7*(Electrico!$B$18-Electrico!$B$16*H8+Electrico!$B$17*I8-Electrico!$B$10*J8+Electrico!$B$11*K8-Electrico!$B$16*L8+Electrico!$B$17*M8)+0.3*F8 -> 5690.1242 | G9: =0.7*(-Electrico!$B$16*I8-Electrico!$B$17*H8-Electrico!$B$10*K8-Electrico!$B$11*J8-Electrico!$B$16*M8-Electrico!$B$17*L8)+0.3*G8 -> -363.80673 | H9: =J9+(Parametros!$E$33*1000*B9+Parametros!$E$34*1000*C9)/(3*(B9^2+C9^2)) -> 9.7373747 | I9: =K9+(Parametros!$E$33*1000*C9-Parametros!$E$34*1000*B9)/(3*(B9^2+C9^2)) -> -5.7703857 | J9: =L9+(Parametros!$E$33*1000*D9+Parametros!$E$34*1000*E9)/(3*(D9^2+E9^2)) -> 9.7163199 | K9: =M9+(Parametros!$E$33*1000*E9-Parametros!$E$34*1000*D9)/(3*(D9^2+E9^2)) -> -5.6285949 | L9: =(Demanda!$G$21*1000*F9+Demanda!$G$24*1000*G9)/(3*(F9^2+G9^2)) -> 9.6951162 | M9: =(Demanda!$G$21*1000*G9-Demanda!$G$24*1000*F9)/(3*(F9^2+G9^2)) -> -5.4852878 | N9: =SQRT(F9^2+G9^2)*SQRT(3)*Parametros!$E$29/(Parametros!$E$27*1000) -> 375.2769 | O9: =SQRT(J9^2+K9^2) -> 11.228889 | P9: =3*O9^2*Electrico!$B$10/1000 -> 2.0549446 | Q9: =MAX(ABS(B9-B8),ABS(C9-C8),ABS(D9-D8),ABS(E9-E8),ABS(F9-F8),ABS(G9-G8)) -> 105.62165
A10: 3 | B10: =0.7*(Electrico!$B$18-Electrico!$B$16*H9+Electrico!$B$17*I9)+0.3*B9 -> 5886.0993 | C10: =0.7*(-Electrico!$B$16*I9-Electrico!$B$17*H9)+0.3*C9 -> -194.37667 | D10: =0.7*(Electrico!$B$18-Electrico!$B$16*H9+Electrico!$B$17*I9-Electrico!$B$10*J9+Electrico!$B$11*K9)+0.3*D9 -> 5818.3352 | E10: =0.7*(-Electrico!$B$16*I9-Electrico!$B$17*H9-Electrico!$B$10*K9-Electrico!$B$11*J9)+0.3*E9 -> -194.34025 | F10: =0.7*(Electrico!$B$18-Electrico!$B$16*H9+Electrico!$B$17*I9-Electrico!$B$10*J9+Electrico!$B$11*K9-Electrico!$B$16*L9+Electrico!$B$17*M9)+0.3*F9 -> 5648.9495 | G10: =0.7*(-Electrico!$B$16*I9-Electrico!$B$17*H9-Electrico!$B$10*K9-Electrico!$B$11*J9-Electrico!$B$16*M9-Electrico!$B$17*L9)+0.3*G9 -> -389.1022 | H10: =J10+(Parametros!$E$33*1000*B10+Parametros!$E$34*1000*C10)/(3*(B10^2+C10^2)) -> 9.7770447 | I10: =K10+(Parametros!$E$33*1000*C10-Parametros!$E$34*1000*B10)/(3*(B10^2+C10^2)) -> -5.8576391 | J10: =L10+(Parametros!$E$33*1000*D10+Parametros!$E$34*1000*E10)/(3*(D10^2+E10^2)) -> 9.7562588 | K10: =M10+(Parametros!$E$33*1000*E10-Parametros!$E$34*1000*D10)/(3*(D10^2+E10^2)) -> -5.7153762 | L10: =(Demanda!$G$21*1000*F10+Demanda!$G$24*1000*G10)/(3*(F10^2+G10^2)) -> 9.7352856 | M10: =(Demanda!$G$21*1000*G10-Demanda!$G$24*1000*F10)/(3*(F10^2+G10^2)) -> -5.5714503 | N10: =SQRT(F10^2+G10^2)*SQRT(3)*Parametros!$E$29/(Parametros!$E$27*1000) -> 372.68313 | O10: =SQRT(J10^2+K10^2) -> 11.307082 | P10: =3*O10^2*Electrico!$B$10/1000 -> 2.0836637 | Q10: =MAX(ABS(B10-B9),ABS(C10-C9),ABS(D10-D9),ABS(E10-E9),ABS(F10-F9),ABS(G10-G9)) -> 41.174705
A11: 4 | B11: =0.7*(Electrico!$B$18-Electrico!$B$16*H10+Electrico!$B$17*I10)+0.3*B10 -> 5879.1245 | C11: =0.7*(-Electrico!$B$16*I10-Electrico!$B$17*H10)+0.3*C10 -> -198.68361 | D11: =0.7*(Electrico!$B$18-Electrico!$B$16*H10+Electrico!$B$17*I10-Electrico!$B$10*J10+Electrico!$B$11*K10)+0.3*D10 -> 5809.326 | E11: =0.7*(-Electrico!$B$16*I10-Electrico!$B$17*H10-Electrico!$B$10*K10-Electrico!$B$11*J10)+0.3*E10 -> -198.05106 | F11: =0.7*(Electrico!$B$18-Electrico!$B$16*H10+Electrico!$B$17*I10-Electrico!$B$10*J10+Electrico!$B$11*K10-Electrico!$B$16*L10+Electrico!$B$17*M10)+0.3*F10 -> 5633.1297 | G11: =0.7*(-Electrico!$B$16*I10-Electrico!$B$17*H10-Electrico!$B$10*K10-Electrico!$B$11*J10-Electrico!$B$16*M10-Electrico!$B$17*L10)+0.3*G10 -> -397.1575 | H11: =J11+(Parametros!$E$33*1000*B11+Parametros!$E$34*1000*C11)/(3*(B11^2+C11^2)) -> 9.7940944 | I11: =K11+(Parametros!$E$33*1000*C11-Parametros!$E$34*1000*B11)/(3*(B11^2+C11^2)) -> -5.8888353 | J11: =L11+(Parametros!$E$33*1000*D11+Parametros!$E$34*1000*E11)/(3*(D11^2+E11^2)) -> 9.7733942 | K11: =M11+(Parametros!$E$33*1000*E11-Parametros!$E$34*1000*D11)/(3*(D11^2+E11^2)) -> -5.7463913 | L11: =(Demanda!$G$21*1000*F11+Demanda!$G$24*1000*G11)/(3*(F11^2+G11^2)) -> 9.7524884 | M11: =(Demanda!$G$21*1000*G11-Demanda!$G$24*1000*F11)/(3*(F11^2+G11^2)) -> -5.602231 | N11: =SQRT(F11^2+G11^2)*SQRT(3)*Parametros!$E$29/(Parametros!$E$27*1000) -> 371.68129 | O11: =SQRT(J11^2+K11^2) -> 11.337559 | P11: =3*O11^2*Electrico!$B$10/1000 -> 2.0949113 | Q11: =MAX(ABS(B11-B10),ABS(C11-C10),ABS(D11-D10),ABS(E11-E10),ABS(F11-F10),ABS(G11-G10)) -> 15.819782
A12: 5 | B12: =0.7*(Electrico!$B$18-Electrico!$B$16*H11+Electrico!$B$17*I11)+0.3*B11 -> 5876.4601 | C12: =0.7*(-Electrico!$B$16*I11-Electrico!$B$17*H11)+0.3*C11 -> -200.14763 | D12: =0.7*(Electrico!$B$18-Electrico!$B$16*H11+Electrico!$B$17*I11-Electrico!$B$10*J11+Electrico!$B$11*K11)+0.3*D11 -> 5805.919 | E12: =0.7*(-Electrico!$B$16*I11-Electrico!$B$17*H11-Electrico!$B$10*K11-Electrico!$B$11*J11)+0.3*E11 -> -199.25538 | F12: =0.7*(Electrico!$B$18-Electrico!$B$16*H11+Electrico!$B$17*I11-Electrico!$B$10*J11+Electrico!$B$11*K11-Electrico!$B$16*L11+Electrico!$B$17*M11)+0.3*F11 -> 5627.1138 | G12: =0.7*(-Electrico!$B$16*I11-Electrico!$B$17*H11-Electrico!$B$10*K11-Electrico!$B$11*J11-Electrico!$B$16*M11-Electrico!$B$17*L11)+0.3*G11 -> -399.84106 | H12: =J12+(Parametros!$E$33*1000*B12+Parametros!$E$34*1000*C12)/(3*(B12^2+C12^2)) -> 9.8010086 | I12: =K12+(Parametros!$E$33*1000*C12-Parametros!$E$34*1000*B12)/(3*(B12^2+C12^2)) -> -5.9001273 | J12: =L12+(Parametros!$E$33*1000*D12+Parametros!$E$34*1000*E12)/(3*(D12^2+E12^2)) -> 9.7803369 | K12: =M12+(Parametros!$E$33*1000*E12-Parametros!$E$34*1000*D12)/(3*(D12^2+E12^2)) -> -5.7576145 | L12: =(Demanda!$G$21*1000*F12+Demanda!$G$24*1000*G12)/(3*(F12^2+G12^2)) -> 9.7594517 | M12: =(Demanda!$G$21*1000*G12-Demanda!$G$24*1000*F12)/(3*(F12^2+G12^2)) -> -5.613366 | N12: =SQRT(F12^2+G12^2)*SQRT(3)*Parametros!$E$29/(Parametros!$E$27*1000) -> 371.29879 | O12: =SQRT(J12^2+K12^2) -> 11.349234 | P12: =3*O12^2*Electrico!$B$10/1000 -> 2.0992281 | Q12: =MAX(ABS(B12-B11),ABS(C12-C11),ABS(D12-D11),ABS(E12-E11),ABS(F12-F11),ABS(G12-G11)) -> 6.0158732
A13: 6 | B13: =0.7*(Electrico!$B$18-Electrico!$B$16*H12+Electrico!$B$17*I12)+0.3*B12 -> 5875.4512 | C13: =0.7*(-Electrico!$B$16*I12-Electrico!$B$17*H12)+0.3*C12 -> -200.66128 | D13: =0.7*(Electrico!$B$18-Electrico!$B$16*H12+Electrico!$B$17*I12-Electrico!$B$10*J12+Electrico!$B$11*K12)+0.3*D12 -> 5804.6366 | E13: =0.7*(-Electrico!$B$16*I12-Electrico!$B$17*H12-Electrico!$B$10*K12-Electrico!$B$11*J12)+0.3*E12 -> -199.66347 | F13: =0.7*(Electrico!$B$18-Electrico!$B$16*H12+Electrico!$B$17*I12-Electrico!$B$10*J12+Electrico!$B$11*K12-Electrico!$B$16*L12+Electrico!$B$17*M12)+0.3*F12 -> 5624.8415 | G13: =0.7*(-Electrico!$B$16*I12-Electrico!$B$17*H12-Electrico!$B$10*K12-Electrico!$B$11*J12-Electrico!$B$16*M12-Electrico!$B$17*L12)+0.3*G12 -> -400.76872 | H13: =J13+(Parametros!$E$33*1000*B13+Parametros!$E$34*1000*C13)/(3*(B13^2+C13^2)) -> 9.8037188 | I13: =K13+(Parametros!$E$33*1000*C13-Parametros!$E$34*1000*B13)/(3*(B13^2+C13^2)) -> -5.9042578 | J13: =L13+(Parametros!$E$33*1000*D13+Parametros!$E$34*1000*E13)/(3*(D13^2+E13^2)) -> 9.7830569 | K13: =M13+(Parametros!$E$33*1000*E13-Parametros!$E$34*1000*D13)/(3*(D13^2+E13^2)) -> -5.7617191 | L13: =(Demanda!$G$21*1000*F13+Demanda!$G$24*1000*G13)/(3*(F13^2+G13^2)) -> 9.7621784 | M13: =(Demanda!$G$21*1000*G13-Demanda!$G$24*1000*F13)/(3*(F13^2+G13^2)) -> -5.6174375 | N13: =SQRT(F13^2+G13^2)*SQRT(3)*Parametros!$E$29/(Parametros!$E$27*1000) -> 371.15395 | O13: =SQRT(J13^2+K13^2) -> 11.353661 | P13: =3*O13^2*Electrico!$B$10/1000 -> 2.1008659 | Q13: =MAX(ABS(B13-B12),ABS(C13-C12),ABS(D13-D12),ABS(E13-E12),ABS(F13-F12),ABS(G13-G12)) -> 2.2722738
A14: 7 | B14: =0.7*(Electrico!$B$18-Electrico!$B$16*H13+Electrico!$B$17*I13)+0.3*B13 -> 5875.0712 | C14: =0.7*(-Electrico!$B$16*I13-Electrico!$B$17*H13)+0.3*C13 -> -200.84558 | D14: =0.7*(Electrico!$B$18-Electrico!$B$16*H13+Electrico!$B$17*I13-Electrico!$B$10*J13+Electrico!$B$11*K13)+0.3*D13 -> 5804.1553 | E14: =0.7*(-Electrico!$B$16*I13-Electrico!$B$17*H13-Electrico!$B$10*K13-Electrico!$B$11*J13)+0.3*E13 -> -199.80638 | F14: =0.7*(Electrico!$B$18-Electrico!$B$16*H13+Electrico!$B$17*I13-Electrico!$B$10*J13+Electrico!$B$11*K13-Electrico!$B$16*L13+Electrico!$B$17*M13)+0.3*F13 -> 5623.9869 | G14: =0.7*(-Electrico!$B$16*I13-Electrico!$B$17*H13-Electrico!$B$10*K13-Electrico!$B$11*J13-Electrico!$B$16*M13-Electrico!$B$17*L13)+0.3*G13 -> -401.09818 | H14: =J14+(Parametros!$E$33*1000*B14+Parametros!$E$34*1000*C14)/(3*(B14^2+C14^2)) -> 9.8047605 | I14: =K14+(Parametros!$E$33*1000*C14-Parametros!$E$34*1000*B14)/(3*(B14^2+C14^2)) -> -5.9057801 | J14: =L14+(Parametros!$E$33*1000*D14+Parametros!$E$34*1000*E14)/(3*(D14^2+E14^2)) -> 9.7841021 | K14: =M14+(Parametros!$E$33*1000*E14-Parametros!$E$34*1000*D14)/(3*(D14^2+E14^2)) -> -5.7632317 | L14: =(Demanda!$G$21*1000*F14+Demanda!$G$24*1000*G14)/(3*(F14^2+G14^2)) -> 9.7632258 | M14: =(Demanda!$G$21*1000*G14-Demanda!$G$24*1000*F14)/(3*(F14^2+G14^2)) -> -5.6189377 | N14: =SQRT(F14^2+G14^2)*SQRT(3)*Parametros!$E$29/(Parametros!$E$27*1000) -> 371.09938 | O14: =SQRT(J14^2+K14^2) -> 11.355329 | P14: =3*O14^2*Electrico!$B$10/1000 -> 2.1014833 | Q14: =MAX(ABS(B14-B13),ABS(C14-C13),ABS(D14-D13),ABS(E14-E13),ABS(F14-F13),ABS(G14-G13)) -> 0.85460339
A15: 8 | B15: =0.7*(Electrico!$B$18-Electrico!$B$16*H14+Electrico!$B$17*I14)+0.3*B14 -> 5874.9286 | C15: =0.7*(-Electrico!$B$16*I14-Electrico!$B$17*H14)+0.3*C14 -> -200.91271 | D15: =0.7*(Electrico!$B$18-Electrico!$B$16*H14+Electrico!$B$17*I14-Electrico!$B$10*J14+Electrico!$B$11*K14)+0.3*D14 -> 5803.975 | E15: =0.7*(-Electrico!$B$16*I14-Electrico!$B$17*H14-Electrico!$B$10*K14-Electrico!$B$11*J14)+0.3*E14 -> -199.8576 | F15: =0.7*(Electrico!$B$18-Electrico!$B$16*H14+Electrico!$B$17*I14-Electrico!$B$10*J14+Electrico!$B$11*K14-Electrico!$B$16*L14+Electrico!$B$17*M14)+0.3*F14 -> 5623.6664 | G15: =0.7*(-Electrico!$B$16*I14-Electrico!$B$17*H14-Electrico!$B$10*K14-Electrico!$B$11*J14-Electrico!$B$16*M14-Electrico!$B$17*L14)+0.3*G14 -> -401.21737 | H15: =J15+(Parametros!$E$33*1000*B15+Parametros!$E$34*1000*C15)/(3*(B15^2+C15^2)) -> 9.8051562 | I15: =K15+(Parametros!$E$33*1000*C15-Parametros!$E$34*1000*B15)/(3*(B15^2+C15^2)) -> -5.906344 | J15: =L15+(Parametros!$E$33*1000*D15+Parametros!$E$34*1000*E15)/(3*(D15^2+E15^2)) -> 9.7844991 | K15: =M15+(Parametros!$E$33*1000*E15-Parametros!$E$34*1000*D15)/(3*(D15^2+E15^2)) -> -5.7637919 | L15: =(Demanda!$G$21*1000*F15+Demanda!$G$24*1000*G15)/(3*(F15^2+G15^2)) -> 9.7636236 | M15: =(Demanda!$G$21*1000*G15-Demanda!$G$24*1000*F15)/(3*(F15^2+G15^2)) -> -5.6194933 | N15: =SQRT(F15^2+G15^2)*SQRT(3)*Parametros!$E$29/(Parametros!$E$27*1000) -> 371.0789 | O15: =SQRT(J15^2+K15^2) -> 11.355955 | P15: =3*O15^2*Electrico!$B$10/1000 -> 2.1017151 | Q15: =MAX(ABS(B15-B14),ABS(C15-C14),ABS(D15-D14),ABS(E15-E14),ABS(F15-F14),ABS(G15-G14)) -> 0.32056402
A16: 9 | B16: =0.7*(Electrico!$B$18-Electrico!$B$16*H15+Electrico!$B$17*I15)+0.3*B15 -> 5874.8751 | C16: =0.7*(-Electrico!$B$16*I15-Electrico!$B$17*H15)+0.3*C15 -> -200.9374 | D16: =0.7*(Electrico!$B$18-Electrico!$B$16*H15+Electrico!$B$17*I15-Electrico!$B$10*J15+Electrico!$B$11*K15)+0.3*D15 -> 5803.9076 | E16: =0.7*(-Electrico!$B$16*I15-Electrico!$B$17*H15-Electrico!$B$10*K15-Electrico!$B$11*J15)+0.3*E15 -> -199.87624 | F16: =0.7*(Electrico!$B$18-Electrico!$B$16*H15+Electrico!$B$17*I15-Electrico!$B$10*J15+Electrico!$B$11*K15-Electrico!$B$16*L15+Electrico!$B$17*M15)+0.3*F15 -> 5623.5463 | G16: =0.7*(-Electrico!$B$16*I15-Electrico!$B$17*H15-Electrico!$B$10*K15-Electrico!$B$11*J15-Electrico!$B$16*M15-Electrico!$B$17*L15)+0.3*G15 -> -401.26102 | H16: =J16+(Parametros!$E$33*1000*B16+Parametros!$E$34*1000*C16)/(3*(B16^2+C16^2)) -> 9.8053056 | I16: =K16+(Parametros!$E$33*1000*C16-Parametros!$E$34*1000*B16)/(3*(B16^2+C16^2)) -> -5.9065536 | J16: =L16+(Parametros!$E$33*1000*D16+Parametros!$E$34*1000*E16)/(3*(D16^2+E16^2)) -> 9.7846489 | K16: =M16+(Parametros!$E$33*1000*E16-Parametros!$E$34*1000*D16)/(3*(D16^2+E16^2)) -> -5.7640001 | L16: =(Demanda!$G$21*1000*F16+Demanda!$G$24*1000*G16)/(3*(F16^2+G16^2)) -> 9.7637737 | M16: =(Demanda!$G$21*1000*G16-Demanda!$G$24*1000*F16)/(3*(F16^2+G16^2)) -> -5.6196997 | N16: =SQRT(F16^2+G16^2)*SQRT(3)*Parametros!$E$29/(Parametros!$E$27*1000) -> 371.07122 | O16: =SQRT(J16^2+K16^2) -> 11.35619 | P16: =3*O16^2*Electrico!$B$10/1000 -> 2.101802 | Q16: =MAX(ABS(B16-B15),ABS(C16-C15),ABS(D16-D15),ABS(E16-E15),ABS(F16-F15),ABS(G16-G15)) -> 0.1200482
A17: 10 | B17: =0.7*(Electrico!$B$18-Electrico!$B$16*H16+Electrico!$B$17*I16)+0.3*B16 -> 5874.8551 | C17: =0.7*(-Electrico!$B$16*I16-Electrico!$B$17*H16)+0.3*C16 -> -200.94653 | D17: =0.7*(Electrico!$B$18-Electrico!$B$16*H16+Electrico!$B$17*I16-Electrico!$B$10*J16+Electrico!$B$11*K16)+0.3*D16 -> 5803.8824 | E17: =0.7*(-Electrico!$B$16*I16-Electrico!$B$17*H16-Electrico!$B$10*K16-Electrico!$B$11*J16)+0.3*E16 -> -199.88309 | F17: =0.7*(Electrico!$B$18-Electrico!$B$16*H16+Electrico!$B$17*I16-Electrico!$B$10*J16+Electrico!$B$11*K16-Electrico!$B$16*L16+Electrico!$B$17*M16)+0.3*F16 -> 5623.5014 | G17: =0.7*(-Electrico!$B$16*I16-Electrico!$B$17*H16-Electrico!$B$10*K16-Electrico!$B$11*J16-Electrico!$B$16*M16-Electrico!$B$17*L16)+0.3*G16 -> -401.27712 | H17: =J17+(Parametros!$E$33*1000*B17+Parametros!$E$34*1000*C17)/(3*(B17^2+C17^2)) -> 9.8053617 | I17: =K17+(Parametros!$E$33*1000*C17-Parametros!$E$34*1000*B17)/(3*(B17^2+C17^2)) -> -5.9066316 | J17: =L17+(Parametros!$E$33*1000*D17+Parametros!$E$34*1000*E17)/(3*(D17^2+E17^2)) -> 9.7847052 | K17: =M17+(Parametros!$E$33*1000*E17-Parametros!$E$34*1000*D17)/(3*(D17^2+E17^2)) -> -5.7640776 | L17: =(Demanda!$G$21*1000*F17+Demanda!$G$24*1000*G17)/(3*(F17^2+G17^2)) -> 9.7638301 | M17: =(Demanda!$G$21*1000*G17-Demanda!$G$24*1000*F17)/(3*(F17^2+G17^2)) -> -5.6197766 | N17: =SQRT(F17^2+G17^2)*SQRT(3)*Parametros!$E$29/(Parametros!$E$27*1000) -> 371.06835 | O17: =SQRT(J17^2+K17^2) -> 11.356278 | P17: =3*O17^2*Electrico!$B$10/1000 -> 2.1018346 | Q17: =MAX(ABS(B17-B16),ABS(C17-C16),ABS(D17-D16),ABS(E17-E16),ABS(F17-F16),ABS(G17-G16)) -> 0.044912052
A18: 11 | B18: =0.7*(Electrico!$B$18-Electrico!$B$16*H17+Electrico!$B$17*I17)+0.3*B17 -> 5874.8477 | C18: =0.7*(-Electrico!$B$16*I17-Electrico!$B$17*H17)+0.3*C17 -> -200.94992 | D18: =0.7*(Electrico!$B$18-Electrico!$B$16*H17+Electrico!$B$17*I17-Electrico!$B$10*J17+Electrico!$B$11*K17)+0.3*D17 -> 5803.873 | E18: =0.7*(-Electrico!$B$16*I17-Electrico!$B$17*H17-Electrico!$B$10*K17-Electrico!$B$11*J17)+0.3*E17 -> -199.88563 | F18: =0.7*(Electrico!$B$18-Electrico!$B$16*H17+Electrico!$B$17*I17-Electrico!$B$10*J17+Electrico!$B$11*K17-Electrico!$B$16*L17+Electrico!$B$17*M17)+0.3*F17 -> 5623.4846 | G18: =0.7*(-Electrico!$B$16*I17-Electrico!$B$17*H17-Electrico!$B$10*K17-Electrico!$B$11*J17-Electrico!$B$16*M17-Electrico!$B$17*L17)+0.3*G17 -> -401.28309 | H18: =J18+(Parametros!$E$33*1000*B18+Parametros!$E$34*1000*C18)/(3*(B18^2+C18^2)) -> 9.8053828 | I18: =K18+(Parametros!$E$33*1000*C18-Parametros!$E$34*1000*B18)/(3*(B18^2+C18^2)) -> -5.9066607 | J18: =L18+(Parametros!$E$33*1000*D18+Parametros!$E$34*1000*E18)/(3*(D18^2+E18^2)) -> 9.7847263 | K18: =M18+(Parametros!$E$33*1000*E18-Parametros!$E$34*1000*D18)/(3*(D18^2+E18^2)) -> -5.7641065 | L18: =(Demanda!$G$21*1000*F18+Demanda!$G$24*1000*G18)/(3*(F18^2+G18^2)) -> 9.7638512 | M18: =(Demanda!$G$21*1000*G18-Demanda!$G$24*1000*F18)/(3*(F18^2+G18^2)) -> -5.6198053 | N18: =SQRT(F18^2+G18^2)*SQRT(3)*Parametros!$E$29/(Parametros!$E$27*1000) -> 371.06727 | O18: =SQRT(J18^2+K18^2) -> 11.356311 | P18: =3*O18^2*Electrico!$B$10/1000 -> 2.1018467 | Q18: =MAX(ABS(B18-B17),ABS(C18-C17),ABS(D18-D17),ABS(E18-E17),ABS(F18-F17),ABS(G18-G17)) -> 0.016792137
A19: 12 | B19: =0.7*(Electrico!$B$18-Electrico!$B$16*H18+Electrico!$B$17*I18)+0.3*B18 -> 5874.8449 | C19: =0.7*(-Electrico!$B$16*I18-Electrico!$B$17*H18)+0.3*C18 -> -200.95118 | D19: =0.7*(Electrico!$B$18-Electrico!$B$16*H18+Electrico!$B$17*I18-Electrico!$B$10*J18+Electrico!$B$11*K18)+0.3*D18 -> 5803.8694 | E19: =0.7*(-Electrico!$B$16*I18-Electrico!$B$17*H18-Electrico!$B$10*K18-Electrico!$B$11*J18)+0.3*E18 -> -199.88657 | F19: =0.7*(Electrico!$B$18-Electrico!$B$16*H18+Electrico!$B$17*I18-Electrico!$B$10*J18+Electrico!$B$11*K18-Electrico!$B$16*L18+Electrico!$B$17*M18)+0.3*F18 -> 5623.4784 | G19: =0.7*(-Electrico!$B$16*I18-Electrico!$B$17*H18-Electrico!$B$10*K18-Electrico!$B$11*J18-Electrico!$B$16*M18-Electrico!$B$17*L18)+0.3*G18 -> -401.28531 | H19: =J19+(Parametros!$E$33*1000*B19+Parametros!$E$34*1000*C19)/(3*(B19^2+C19^2)) -> 9.8053907 | I19: =K19+(Parametros!$E$33*1000*C19-Parametros!$E$34*1000*B19)/(3*(B19^2+C19^2)) -> -5.9066716 | J19: =L19+(Parametros!$E$33*1000*D19+Parametros!$E$34*1000*E19)/(3*(D19^2+E19^2)) -> 9.7847342 | K19: =M19+(Parametros!$E$33*1000*E19-Parametros!$E$34*1000*D19)/(3*(D19^2+E19^2)) -> -5.7641173 | L19: =(Demanda!$G$21*1000*F19+Demanda!$G$24*1000*G19)/(3*(F19^2+G19^2)) -> 9.7638591 | M19: =(Demanda!$G$21*1000*G19-Demanda!$G$24*1000*F19)/(3*(F19^2+G19^2)) -> -5.619816 | N19: =SQRT(F19^2+G19^2)*SQRT(3)*Parametros!$E$29/(Parametros!$E$27*1000) -> 371.06687 | O19: =SQRT(J19^2+K19^2) -> 11.356323 | P19: =3*O19^2*Electrico!$B$10/1000 -> 2.1018513 | Q19: =MAX(ABS(B19-B18),ABS(C19-C18),ABS(D19-D18),ABS(E19-E18),ABS(F19-F18),ABS(G19-G18)) -> 0.0062760779
... A66: 59 | B66: =0.7*(Electrico!$B$18-Electrico!$B$16*H65+Electrico!$B$17*I65)+0.3*B65 -> 5874.8432 | C66: =0.7*(-Electrico!$B$16*I65-Electrico!$B$17*H65)+0.3*C65 -> -200.95193 | D66: =0.7*(Electrico!$B$18-Electrico!$B$16*H65+Electrico!$B$17*I65-Electrico!$B$10*J65+Electrico!$B$11*K65)+0.3*D65 -> 5803.8673 | E66: =0.7*(-Electrico!$B$16*I65-Electrico!$B$17*H65-Electrico!$B$10*K65-Electrico!$B$11*J65)+0.3*E65 -> -199.88713 | F66: =0.7*(Electrico!$B$18-Electrico!$B$16*H65+Electrico!$B$17*I65-Electrico!$B$10*J65+Electrico!$B$11*K65-Electrico!$B$16*L65+Electrico!$B$17*M65)+0.3*F65 -> 5623.4746 | G66: =0.7*(-Electrico!$B$16*I65-Electrico!$B$17*H65-Electrico!$B$10*K65-Electrico!$B$11*J65-Electrico!$B$16*M65-Electrico!$B$17*L65)+0.3*G65 -> -401.28663 | H66: =J66+(Parametros!$E$33*1000*B66+Parametros!$E$34*1000*C66)/(3*(B66^2+C66^2)) -> 9.8053954 | I66: =K66+(Parametros!$E$33*1000*C66-Parametros!$E$34*1000*B66)/(3*(B66^2+C66^2)) -> -5.906678 | J66: =L66+(Parametros!$E$33*1000*D66+Parametros!$E$34*1000*E66)/(3*(D66^2+E66^2)) -> 9.7847389 | K66: =M66+(Parametros!$E$33*1000*E66-Parametros!$E$34*1000*D66)/(3*(D66^2+E66^2)) -> -5.7641237 | L66: =(Demanda!$G$21*1000*F66+Demanda!$G$24*1000*G66)/(3*(F66^2+G66^2)) -> 9.7638639 | M66: =(Demanda!$G$21*1000*G66-Demanda!$G$24*1000*F66)/(3*(F66^2+G66^2)) -> -5.6198223 | N66: =SQRT(F66^2+G66^2)*SQRT(3)*Parametros!$E$29/(Parametros!$E$27*1000) -> 371.06663 | O66: =SQRT(J66^2+K66^2) -> 11.35633 | P66: =3*O66^2*Electrico!$B$10/1000 -> 2.101854 | Q66: =MAX(ABS(B66-B65),ABS(C66-C65),ABS(D66-D65),ABS(E66-E65),ABS(F66-F65),ABS(G66-G65)) -> 0

Sheet Cortocircuito
A2: CORTOCIRCUITO TRIFÁSICO SIMÉTRICO
A6: Estado de fuente | B6: Punto | C6: Xd (pu) | D6: Vbase (V) | E6: Re Z (Ω) | F6: Im Z (Ω) | G6: |Z| (Ω) | H6: Ik3 (A)
A7: Subtransitorio | B7: MT salida | C7: =Parametros!$E$38 -> 0.2 | D7: =Parametros!$E$27*1000 -> 10000 | E7: =Parametros!$E$37*Electrico!$B$15+1*Electrico!$B$16+0*Electrico!$B$10 -> 12.96 | F7: =C7*Electrico!$B$15+1*Electrico!$B$17+0*Electrico!$B$11 -> 103.48187 | G7: =SQRT(E7^2+F7^2) -> 104.29027 | H7: =D7/SQRT(3)/G7 -> 55.359938
A8: Subtransitorio | B8: MT llegada | C8: =Parametros!$E$38 -> 0.2 | D8: =Parametros!$E$27*1000 -> 10000 | E8: =Parametros!$E$37*Electrico!$B$15+1*Electrico!$B$16+1*Electrico!$B$10 -> 18.392569 | F8: =C8*Electrico!$B$15+1*Electrico!$B$17+1*Electrico!$B$11 -> 106.57334 | G8: =SQRT(E8^2+F8^2) -> 108.1488 | H8: =D8/SQRT(3)/G8 -> 53.384805
A9: Subtransitorio | B9: BT llegada | C9: =Parametros!$E$38 -> 0.2 | D9: =Parametros!$E$27*1000 -> 10000 | E9: =Parametros!$E$37*Electrico!$B$15+2*Electrico!$B$16+1*Electrico!$B$10 -> 23.352569 | F9: =C9*Electrico!$B$15+2*Electrico!$B$17+1*Electrico!$B$11 -> 130.05521 | G9: =SQRT(E9^2+F9^2) -> 132.13516 | H9: =D9/SQRT(3)/G9*D9/Parametros!$E$29 -> 1149.8399
A10: Transitorio | B10: MT salida | C10: =Parametros!$E$39 -> 0.3 | D10: =Parametros!$E$27*1000 -> 10000 | E10: =Parametros!$E$37*Electrico!$B$15+1*Electrico!$B$16+0*Electrico!$B$10 -> 12.96 | F10: =C10*Electrico!$B$15+1*Electrico!$B$17+0*Electrico!$B$11 -> 143.48187 | G10: =SQRT(E10^2+F10^2) -> 144.06599 | H10: =D10/SQRT(3)/G10 -> 40.075403
A11: Transitorio | B11: MT llegada | C11: =Parametros!$E$39 -> 0.3 | D11: =Parametros!$E$27*1000 -> 10000 | E11: =Parametros!$E$37*Electrico!$B$15+1*Electrico!$B$16+1*Electrico!$B$10 -> 18.392569 | F11: =C11*Electrico!$B$15+1*Electrico!$B$17+1*Electrico!$B$11 -> 146.57334 | G11: =SQRT(E11^2+F11^2) -> 147.72282 | H11: =D11/SQRT(3)/G11 -> 39.083351
A12: Transitorio | B12: BT llegada | C12: =Parametros!$E$39 -> 0.3 | D12: =Parametros!$E$27*1000 -> 10000 | E12: =Parametros!$E$37*Electrico!$B$15+2*Electrico!$B$16+1*Electrico!$B$10 -> 23.352569 | F12: =C12*Electrico!$B$15+2*Electrico!$B$17+1*Electrico!$B$11 -> 170.05521 | G12: =SQRT(E12^2+F12^2) -> 171.65115 | H12: =D12/SQRT(3)/G12*D12/Parametros!$E$29 -> 885.13405
A13: Sostenido | B13: MT salida | C13: =Parametros!$E$40 -> 1.8 | D13: =Parametros!$E$27*1000 -> 10000 | E13: =Parametros!$E$37*Electrico!$B$15+1*Electrico!$B$16+0*Electrico!$B$10 -> 12.96 | F13: =C13*Electrico!$B$15+1*Electrico!$B$17+0*Electrico!$B$11 -> 743.48187 | G13: =SQRT(E13^2+F13^2) -> 743.59482 | H13: =D13/SQRT(3)/G13 -> 7.7643127
A14: Sostenido | B14: MT llegada | C14: =Parametros!$E$40 -> 1.8 | D14: =Parametros!$E$27*1000 -> 10000 | E14: =Parametros!$E$37*Electrico!$B$15+1*Electrico!$B$16+1*Electrico!$B$10 -> 18.392569 | F14: =C14*Electrico!$B$15+1*Electrico!$B$17+1*Electrico!$B$11 -> 746.57334 | G14: =SQRT(E14^2+F14^2) -> 746.79987 | H14: =D14/SQRT(3)/G14 -> 7.7309905
A15: Sostenido | B15: BT llegada | C15: =Parametros!$E$40 -> 1.8 | D15: =Parametros!$E$27*1000 -> 10000 | E15: =Parametros!$E$37*Electrico!$B$15+2*Electrico!$B$16+1*Electrico!$B$10 -> 23.352569 | F15: =C15*Electrico!$B$15+2*Electrico!$B$17+1*Electrico!$B$11 -> 770.05521 | G15: =SQRT(E15^2+F15^2) -> 770.40923 | H15: =D15/SQRT(3)/G15*D15/Parametros!$E$29 -> 197.21244
A19: Fuente: impedancias tipo del generador y transformadores.
A21: No incluye decremento temporal ni selección de ajustes del relé.

Sheet Mecanica
A2: VERIFICACIÓN DE POSTES Y RETENIDAS
A6: Poste | B6: Altura (m) | C6: Empotr. (m) | D6: Momento aplicado (kN·m) | E6: Momento tipo (kN·m) | F6: D/C | G6: Vertical mín. (kN) | H6: Ramales | I6: Tiro (kN) | J6: Rotura adopt. (kN) | K6: T admisible (kN) | L6: Utilización retenida
A7: P001 | B7: =Postes!E7 -> 13 | C7: =Postes!F7 -> 1.9 | D7: 20.571388 | E7: =Parametros!$E$14*Parametros!$E$12*10*Parametros!$E$13*(B7-C7-Parametros!$E$15)/1000 -> 85.41 | F7: =D7/E7 -> 0.24085456 | G7: -4.6649958 | H7: =Postes!J7 -> 1 | I7: 24.506623 | J7: =IF(H7=0,0,ROUNDUP(MAX(Parametros!$E$16,I7/Parametros!$E$17)/10,0)*10) -> 60 | K7: =J7*Parametros!$E$17 -> 54 | L7: =IF(H7=0,0,I7/K7) -> 0.45382635
A8: P002 | B8: =Postes!E8 -> 13 | C8: =Postes!F8 -> 1.9 | D8: 27.257459 | E8: =Parametros!$E$14*Parametros!$E$12*10*Parametros!$E$13*(B8-C8-Parametros!$E$15)/1000 -> 85.41 | F8: =D8/E8 -> 0.31913663 | G8: 0.78112393 | H8: =Postes!J8 -> 0 | I8: 0 | J8: =IF(H8=0,0,ROUNDUP(MAX(Parametros!$E$16,I8/Parametros!$E$17)/10,0)*10) -> 0 | K8: =J8*Parametros!$E$17 -> 0 | L8: =IF(H8=0,0,I8/K8) -> 0
A9: P003 | B9: =Postes!E9 -> 15 | C9: =Postes!F9 -> 2.1 | D9: 30.918951 | E9: =Parametros!$E$14*Parametros!$E$12*10*Parametros!$E$13*(B9-C9-Parametros!$E$15)/1000 -> 99.45 | F9: =D9/E9 -> 0.31089945 | G9: 1.3298384 | H9: =Postes!J9 -> 2 | I9: 26.352028 | J9: =IF(H9=0,0,ROUNDUP(MAX(Parametros!$E$16,I9/Parametros!$E$17)/10,0)*10) -> 60 | K9: =J9*Parametros!$E$17 -> 54 | L9: =IF(H9=0,0,I9/K9) -> 0.48800051
A10: P004 | B10: =Postes!E10 -> 15 | C10: =Postes!F10 -> 2.1 | D10: 42.71534 | E10: =Parametros!$E$14*Parametros!$E$12*10*Parametros!$E$13*(B10-C10-Parametros!$E$15)/1000 -> 99.45 | F10: =D10/E10 -> 0.42951573 | G10: 0.93830087 | H10: =Postes!J10 -> 0 | I10: 0 | J10: =IF(H10=0,0,ROUNDUP(MAX(Parametros!$E$16,I10/Parametros!$E$17)/10,0)*10) -> 0 | K10: =J10*Parametros!$E$17 -> 0 | L10: =IF(H10=0,0,I10/K10) -> 0
A11: P005 | B11: =Postes!E11 -> 15 | C11: =Postes!F11 -> 2.1 | D11: 41.956841 | E11: =Parametros!$E$14*Parametros!$E$12*10*Parametros!$E$13*(B11-C11-Parametros!$E$15)/1000 -> 99.45 | F11: =D11/E11 -> 0.4218888 | G11: -1.1249486 | H11: =Postes!J11 -> 2 | I11: 26.350939 | J11: =IF(H11=0,0,ROUNDUP(MAX(Parametros!$E$16,I11/Parametros!$E$17)/10,0)*10) -> 60 | K11: =J11*Parametros!$E$17 -> 54 | L11: =IF(H11=0,0,I11/K11) -> 0.48798036
A12: P006 | B12: =Postes!E12 -> 17 | C12: =Postes!F12 -> 2.1 | D12: 51.085756 | E12: =Parametros!$E$14*Parametros!$E$12*10*Parametros!$E$13*(B12-C12-Parametros!$E$15)/1000 -> 115.05 | F12: =D12/E12 -> 0.44403091 | G12: 1.0555594 | H12: =Postes!J12 -> 0 | I12: 0 | J12: =IF(H12=0,0,ROUNDUP(MAX(Parametros!$E$16,I12/Parametros!$E$17)/10,0)*10) -> 0 | K12: =J12*Parametros!$E$17 -> 0 | L12: =IF(H12=0,0,I12/K12) -> 0
A13: P007 | B13: =Postes!E13 -> 15 | C13: =Postes!F13 -> 2.1 | D13: 39.155608 | E13: =Parametros!$E$14*Parametros!$E$12*10*Parametros!$E$13*(B13-C13-Parametros!$E$15)/1000 -> 99.45 | F13: =D13/E13 -> 0.39372155 | G13: 0.98969135 | H13: =Postes!J13 -> 2 | I13: 26.044122 | J13: =IF(H13=0,0,ROUNDUP(MAX(Parametros!$E$16,I13/Parametros!$E$17)/10,0)*10) -> 60 | K13: =J13*Parametros!$E$17 -> 54 | L13: =IF(H13=0,0,I13/K13) -> 0.48229856
A14: P008 | B14: =Postes!E14 -> 13 | C14: =Postes!F14 -> 1.9 | D14: 30.961064 | E14: =Parametros!$E$14*Parametros!$E$12*10*Parametros!$E$13*(B14-C14-Parametros!$E$15)/1000 -> 85.41 | F14: =D14/E14 -> 0.36249928 | G14: -0.081600517 | H14: =Postes!J14 -> 2 | I14: 25.988112 | J14: =IF(H14=0,0,ROUNDUP(MAX(Parametros!$E$16,I14/Parametros!$E$17)/10,0)*10) -> 60 | K14: =J14*Parametros!$E$17 -> 54 | L14: =IF(H14=0,0,I14/K14) -> 0.48126134
A15: P009 | B15: =Postes!E15 -> 13 | C15: =Postes!F15 -> 1.9 | D15: 33.094101 | E15: =Parametros!$E$14*Parametros!$E$12*10*Parametros!$E$13*(B15-C15-Parametros!$E$15)/1000 -> 85.41 | F15: =D15/E15 -> 0.38747337 | G15: -0.22040643 | H15: =Postes!J15 -> 2 | I15: 25.988112 | J15: =IF(H15=0,0,ROUNDUP(MAX(Parametros!$E$16,I15/Parametros!$E$17)/10,0)*10) -> 60 | K15: =J15*Parametros!$E$17 -> 54 | L15: =IF(H15=0,0,I15/K15) -> 0.48126134
A16: P010 | B16: =Postes!E16 -> 13 | C16: =Postes!F16 -> 1.9 | D16: 29.918061 | E16: =Parametros!$E$14*Parametros!$E$12*10*Parametros!$E$13*(B16-C16-Parametros!$E$15)/1000 -> 85.41 | F16: =D16/E16 -> 0.35028756 | G16: -1.2796622 | H16: =Postes!J16 -> 2 | I16: 25.942883 | J16: =IF(H16=0,0,ROUNDUP(MAX(Parametros!$E$16,I16/Parametros!$E$17)/10,0)*10) -> 60 | K16: =J16*Parametros!$E$17 -> 54 | L16: =IF(H16=0,0,I16/K16) -> 0.48042375
A17: P011 | B17: =Postes!E17 -> 13 | C17: =Postes!F17 -> 1.9 | D17: 25.660444 | E17: =Parametros!$E$14*Parametros!$E$12*10*Parametros!$E$13*(B17-C17-Parametros!$E$15)/1000 -> 85.41 | F17: =D17/E17 -> 0.3004384 | G17: 1.0460695 | H17: =Postes!J17 -> 2 | I17: 25.373042 | J17: =IF(H17=0,0,ROUNDUP(MAX(Parametros!$E$16,I17/Parametros!$E$17)/10,0)*10) -> 60 | K17: =J17*Parametros!$E$17 -> 54 | L17: =IF(H17=0,0,I17/K17) -> 0.46987116
A18: P012 | B18: =Postes!E18 -> 13 | C18: =Postes!F18 -> 1.9 | D18: 28.859966 | E18: =Parametros!$E$14*Parametros!$E$12*10*Parametros!$E$13*(B18-C18-Parametros!$E$15)/1000 -> 85.41 | F18: =D18/E18 -> 0.33789914 | G18: 0.68548095 | H18: =Postes!J18 -> 2 | I18: 25.373042 | J18: =IF(H18=0,0,ROUNDUP(MAX(Parametros!$E$16,I18/Parametros!$E$17)/10,0)*10) -> 60 | K18: =J18*Parametros!$E$17 -> 54 | L18: =IF(H18=0,0,I18/K18) -> 0.46987116
... A117: P111 | B117: =Postes!E117 -> 13 | C117: =Postes!F117 -> 1.9 | D117: 16.548626 | E117: =Parametros!$E$14*Parametros!$E$12*10*Parametros!$E$13*(B117-C117-Parametros!$E$15)/1000 -> 85.41 | F117: =D117/E117 -> 0.19375513 | G117: 0.54858743 | H117: =Postes!J117 -> 1 | I117: 25.221515 | J117: =IF(H117=0,0,ROUNDUP(MAX(Parametros!$E$16,I117/Parametros!$E$17)/10,0)*10) -> 60 | K117: =J117*Parametros!$E$17 -> 54 | L117: =IF(H117=0,0,I117/K117) -> 0.4670651
A120: Momentos y fuerzas: envolvente del modelo 3D por vano, seis estados y viento cada 15°.

Sheet Estados
A2: CATENARIA: DESARROLLO POR VANO Y ESTADO
A6: Vano | B6: Estado | C6: L (m) | D6: Δz (m) | E6: H resuelto (N) | F6: qv (N/m) | G6: qw (N/m) | H6: q (N/m) | I6: dy (m) | J6: dx (m) | K6: a (m) | L6: x0 (m) | M6: u0 | N6: u1 | O6: Cable (m) | P6: T inicial (N) | Q6: T final (N)
A7: V001 | B7: EDS | C7: 47.146597 | D7: 14.315387 | E7: 2205 | F7: 1.3238977 | G7: 0 | H7: =SQRT(F7^2+G7^2) -> 1.3238977 | I7: =D7*F7/H7 -> 14.315387 | J7: =SQRT(C7^2+D7^2-I7^2) -> 47.146597 | K7: =E7/H7 -> 1665.5365 | L7: =J7/2-K7*ASINH(I7/(2*K7*SINH(J7/(2*K7)))) -> -474.66178 | M7: =-L7/K7 -> 0.28499032 | N7: =(J7-L7)/K7 -> 0.31329748 | O7: =K7*(SINH(N7)-SINH(M7)) -> 49.273525 | P7: =E7*COSH(M7) -> 2295.1522 | Q7: =E7*COSH(N7) -> 2314.1043
A8: V001 | B8: VIENTO | C8: 47.146597 | D8: 14.315387 | E8: 3281.3244 | F8: 1.3238977 | G8: 3.443895 | H8: =SQRT(F8^2+G8^2) -> 3.6895959 | I8: =D8*F8/H8 -> 5.1366351 | J8: =SQRT(C8^2+D8^2-I8^2) -> 49.003539 | K8: =E8/H8 -> 889.3452 | L8: =J8/2-K8*ASINH(I8/(2*K8*SINH(J8/(2*K8)))) -> -68.539318 | M8: =-L8/K8 -> 0.07706717 | N8: =(J8-L8)/K8 -> 0.13216787 | O8: =K8*(SINH(N8)-SINH(M8)) -> 49.278185 | P8: =E8*COSH(M8) -> 3291.0737 | Q8: =E8*COSH(N8) -> 3310.0258
A9: V001 | B9: HIELO | C9: 47.146597 | D9: 14.315387 | E9: 3439.8223 | F9: 3.8554322 | G9: 0 | H9: =SQRT(F9^2+G9^2) -> 3.8554322 | I9: =D9*F9/H9 -> 14.315387 | J9: =SQRT(C9^2+D9^2-I9^2) -> 47.146597 | K9: =E9/H9 -> 892.20149 | L9: =J9/2-K9*ASINH(I9/(2*K9*SINH(J9/(2*K9)))) -> -243.30183 | M9: =-L9/K9 -> 0.2726983 | N9: =(J9-L9)/K9 -> 0.3255413 | O9: =K9*(SINH(N9)-SINH(M9)) -> 49.277268 | P9: =E9*COSH(M9) -> 3568.517 | Q9: =E9*COSH(N9) -> 3623.709
A10: V001 | B10: COMBINADO | C10: 47.146597 | D10: 14.315387 | E10: 3344.7188 | F10: 2.3365115 | G10: 1.4349563 | H10: =SQRT(F10^2+G10^2) -> 2.7419675 | I10: =D10*F10/H10 -> 12.198564 | J10: =SQRT(C10^2+D10^2-I10^2) -> 47.738107 | K10: =E10/H10 -> 1219.8244 | L10: =J10/2-K10*ASINH(I10/(2*K10*SINH(J10/(2*K10)))) -> -284.51837 | M10: =-L10/K10 -> 0.23324535 | N10: =(J10-L10)/K10 -> 0.27238058 | O10: =K10*(SINH(N10)-SINH(M10)) -> 49.274971 | P10: =E10*COSH(M10) -> 3436.1141 | Q10: =E10*COSH(N10) -> 3469.5622
A11: V001 | B11: FRIO | C11: 47.146597 | D11: 14.315387 | E11: 3500.7675 | F11: 1.3238977 | G11: 0 | H11: =SQRT(F11^2+G11^2) -> 1.3238977 | I11: =D11*F11/H11 -> 14.315387 | J11: =SQRT(C11^2+D11^2-I11^2) -> 47.146597 | K11: =E11/H11 -> 2644.2885 | L11: =J11/2-K11*ASINH(I11/(2*K11*SINH(J11/(2*K11)))) -> -767.46494 | M11: =-L11/K11 -> 0.29023496 | N11: =(J11-L11)/K11 -> 0.30806455 | O11: =K11*(SINH(N11)-SINH(M11)) -> 49.272617 | P11: =E11*COSH(M11) -> 3649.2514 | Q11: =E11*COSH(N11) -> 3668.2035
A12: V001 | B12: CALOR_FINAL | C12: 47.146597 | D12: 14.315387 | E12: 363.16545 | F12: 1.3238977 | G12: 0 | H12: =SQRT(F12^2+G12^2) -> 1.3238977 | I12: =D12*F12/H12 -> 14.315387 | J12: =SQRT(C12^2+D12^2-I12^2) -> 47.146597 | K12: =E12/H12 -> 274.31533 | L12: =J12/2-K12*ASINH(I12/(2*K12*SINH(J12/(2*K12)))) -> -58.391107 | M12: =-L12/K12 -> 0.21286126 | N12: =(J12-L12)/K12 -> 0.38473133 | O12: =K12*(SINH(N12)-SINH(M12)) -> 49.327568 | P12: =E12*COSH(M12) -> 371.42406 | Q12: =E12*COSH(N12) -> 390.37617
A13: V002 | B13: EDS | C13: 47.146597 | D13: 13.265247 | E13: 2205 | F13: 1.3238977 | G13: 0 | H13: =SQRT(F13^2+G13^2) -> 1.3238977 | I13: =D13*F13/H13 -> 13.265247 | J13: =SQRT(C13^2+D13^2-I13^2) -> 47.146597 | K13: =E13/H13 -> 1665.5365 | L13: =J13/2-K13*ASINH(I13/(2*K13*SINH(J13/(2*K13)))) -> -439.05727 | M13: =-L13/K13 -> 0.26361312 | N13: =(J13-L13)/K13 -> 0.29192028 | O13: =K13*(SINH(N13)-SINH(M13)) -> 48.978738 | P13: =E13*COSH(M13) -> 2282.0595 | Q13: =E13*COSH(N13) -> 2299.6213
A14: V002 | B14: VIENTO | C14: 47.146597 | D14: 13.265247 | E14: 3268.3777 | F14: 1.3238977 | G14: 3.443895 | H14: =SQRT(F14^2+G14^2) -> 3.6895959 | I14: =D14*F14/H14 -> 4.759825 | J14: =SQRT(C14^2+D14^2-I14^2) -> 48.745384 | K14: =E14/H14 -> 885.83623 | L14: =J14/2-K14*ASINH(I14/(2*K14*SINH(J14/(2*K14)))) -> -61.978544 | M14: =-L14/K14 -> 0.069966143 | N14: =(J14-L14)/K14 -> 0.12499368 | O14: =K14*(SINH(N14)-SINH(M14)) -> 48.983344 | P14: =E14*COSH(M14) -> 3276.3808 | Q14: =E14*COSH(N14) -> 3293.9426
A15: V002 | B15: HIELO | C15: 47.146597 | D15: 13.265247 | E15: 3448.3936 | F15: 3.8554322 | G15: 0 | H15: =SQRT(F15^2+G15^2) -> 3.8554322 | I15: =D15*F15/H15 -> 13.265247 | J15: =SQRT(C15^2+D15^2-I15^2) -> 47.146597 | K15: =E15/H15 -> 894.42466 | L15: =J15/2-K15*ASINH(I15/(2*K15*SINH(J15/(2*K15)))) -> -224.84813 | M15: =-L15/K15 -> 0.25138856 | N15: =(J15-L15)/K15 -> 0.30410021 | O15: =K15*(SINH(N15)-SINH(M15)) -> 48.982477 | P15: =E15*COSH(M15) -> 3557.9313 | Q15: =E15*COSH(N15) -> 3609.0746
A16: V002 | B16: COMBINADO | C16: 47.146597 | D16: 13.265247 | E16: 3345.3173 | F16: 2.3365115 | G16: 1.4349563 | H16: =SQRT(F16^2+G16^2) -> 2.7419675 | I16: =D16*F16/H16 -> 11.303709 | J16: =SQRT(C16^2+D16^2-I16^2) -> 47.654953 | K16: =E16/H16 -> 1220.0427 | L16: =J16/2-K16*ASINH(I16/(2*K16*SINH(J16/(2*K16)))) -> -262.90036 | M16: =-L16/K16 -> 0.21548457 | N16: =(J16-L16)/K16 -> 0.25454464 | O16: =K16*(SINH(N16)-SINH(M16)) -> 48.980171 | P16: =E16*COSH(M16) -> 3423.2858 | Q16: =E16*COSH(N16) -> 3454.2802
A17: V002 | B17: FRIO | C17: 47.146597 | D17: 13.265247 | E17: 3507.7708 | F17: 1.3238977 | G17: 0 | H17: =SQRT(F17^2+G17^2) -> 1.3238977 | I17: =D17*F17/H17 -> 13.265247 | J17: =SQRT(C17^2+D17^2-I17^2) -> 47.146597 | K17: =E17/H17 -> 2649.5783 | L17: =J17/2-K17*ASINH(I17/(2*K17*SINH(J17/(2*K17)))) -> -712.40582 | M17: =-L17/K17 -> 0.26887517 | N17: =(J17-L17)/K17 -> 0.28666917 | O17: =K17*(SINH(N17)-SINH(M17)) -> 48.977822 | P17: =E17*COSH(M17) -> 3635.3317 | Q17: =E17*COSH(N17) -> 3652.8935
A18: V002 | B18: CALOR_FINAL | C18: 47.146597 | D18: 13.265247 | E18: 364.60414 | F18: 1.3238977 | G18: 0 | H18: =SQRT(F18^2+G18^2) -> 1.3238977 | I18: =D18*F18/H18 -> 13.265247 | J18: =SQRT(C18^2+D18^2-I18^2) -> 47.146597 | K18: =E18/H18 -> 275.40204 | L18: =J18/2-K18*ASINH(I18/(2*K18*SINH(J18/(2*K18)))) -> -52.835697 | M18: =-L18/K18 -> 0.19184933 | N18: =(J18-L18)/K18 -> 0.36304122 | O18: =K18*(SINH(N18)-SINH(M18)) -> 49.032665 | P18: =E18*COSH(M18) -> 371.33459 | Q18: =E18*COSH(N18) -> 388.89642
... A666: V110 | B666: CALOR_FINAL | C666: 19.701947 | D666: 0.96862762 | E666: 163.08872 | F666: 1.3238977 | G666: 0 | H666: =SQRT(F666^2+G666^2) -> 1.3238977 | I666: =D666*F666/H666 -> 0.96862762 | J666: =SQRT(C666^2+D666^2-I666^2) -> 19.701947 | K666: =E666/H666 -> 123.18831 | L666: =J666/2-K666*ASINH(I666/(2*K666*SINH(J666/(2*K666)))) -> 3.8034158 | M666: =-L666/K666 -> -0.030874812 | N666: =(J666-L666)/K666 -> 0.12905876 | O666: =K666*(SINH(N666)-SINH(M666)) -> 19.746722 | P666: =E666*COSH(M666) -> 163.16646 | Q666: =E666*COSH(N666) -> 164.44883
A669: H: solución termoelástica del motor. Longitud y esfuerzos de extremo se desarrollan con fórmulas de Excel.

Sheet Postes
A2: PLANILLA DE POSTES Y ARMADOS
A6: Poste | B6: Este (m) | C6: Norte (m) | D6: Cota DEM (m) | E6: Altura (m) | F6: Empotr. (m) | G6: Amarre (m) | H6: Ángulo (°) | I6: Función | J6: Ramales | K6: Postes (ud) | L6: Armados (jgo) | M6: Puentes (m)
A7: P001 | B7: 425715 | C7: 8436650 | D7: 3235.3252 | E7: 13 | F7: 1.9 | G7: 10.6 | H7: 0 | I7: TERMINAL | J7: =IF(I7="SUSPENSION",0,IF(I7="TERMINAL",1,2)) -> 1 | K7: =1 -> 1 | L7: =1 -> 1 | M7: =J7*Parametros!$E$5*Parametros!$E$6 -> 6
A8: P002 | B8: 425745.16 | C8: 8436613.8 | D8: 3249.6406 | E8: 13 | F8: 1.9 | G8: 10.6 | H8: 0 | I8: SUSPENSION | J8: =IF(I8="SUSPENSION",0,IF(I8="TERMINAL",1,2)) -> 0 | K8: =1 -> 1 | L8: =1 -> 1 | M8: =J8*Parametros!$E$5*Parametros!$E$6 -> 0
A9: P003 | B9: 425775.32 | C9: 8436577.5 | D9: 3261.1058 | E9: 15 | F9: 2.1 | G9: 12.4 | H9: 92.594134 | I9: ANCLAJE | J9: =IF(I9="SUSPENSION",0,IF(I9="TERMINAL",1,2)) -> 2 | K9: =1 -> 1 | L9: =1 -> 1 | M9: =J9*Parametros!$E$5*Parametros!$E$6 -> 12
A10: P004 | B10: 425715.11 | C10: 8436531.9 | D10: 3261.1198 | E10: 15 | F10: 2.1 | G10: 12.4 | H10: 0 | I10: SUSPENSION | J10: =IF(I10="SUSPENSION",0,IF(I10="TERMINAL",1,2)) -> 0 | K10: =1 -> 1 | L10: =1 -> 1 | M10: =J10*Parametros!$E$5*Parametros!$E$6 -> 0
A11: P005 | B11: 425654.89 | C11: 8436486.2 | D11: 3260.1333 | E11: 15 | F11: 2.1 | G11: 12.4 | H11: 14.059956 | I11: ANGULO | J11: =IF(I11="SUSPENSION",0,IF(I11="TERMINAL",1,2)) -> 2 | K11: =1 -> 1 | L11: =1 -> 1 | M11: =J11*Parametros!$E$5*Parametros!$E$6 -> 12
A12: P006 | B12: 425610.42 | C12: 8436430.8 | D12: 3265.7274 | E12: 17 | F12: 2.1 | G12: 14.2 | H12: 1.2074183e-06 | I12: SUSPENSION | J12: =IF(I12="SUSPENSION",0,IF(I12="TERMINAL",1,2)) -> 0 | K12: =1 -> 1 | L12: =1 -> 1 | M12: =J12*Parametros!$E$5*Parametros!$E$6 -> 0
A13: P007 | B13: 425565.95 | C13: 8436375.4 | D13: 3270.119 | E13: 15 | F13: 2.1 | G13: 12.4 | H13: 7.8217251 | I13: ANGULO | J13: =IF(I13="SUSPENSION",0,IF(I13="TERMINAL",1,2)) -> 2 | K13: =1 -> 1 | L13: =1 -> 1 | M13: =J13*Parametros!$E$5*Parametros!$E$6 -> 12
A14: P008 | B14: 425536.38 | C14: 8436326.1 | D14: 3270.414 | E14: 13 | F14: 1.9 | G14: 10.6 | H14: 13.486932 | I14: ANGULO | J14: =IF(I14="SUSPENSION",0,IF(I14="TERMINAL",1,2)) -> 2 | K14: =1 -> 1 | L14: =1 -> 1 | M14: =J14*Parametros!$E$5*Parametros!$E$6 -> 12
A15: P009 | B15: 425515.34 | C15: 8436259.2 | D15: 3272.268 | E15: 13 | F15: 1.9 | G15: 10.6 | H15: 0 | I15: ANCLAJE_PROPUESTO | J15: =IF(I15="SUSPENSION",0,IF(I15="TERMINAL",1,2)) -> 2 | K15: =1 -> 1 | L15: =1 -> 1 | M15: =J15*Parametros!$E$5*Parametros!$E$6 -> 12
A16: P010 | B16: 425494.31 | C16: 8436192.4 | D16: 3278.5608 | E16: 13 | F16: 1.9 | G16: 10.6 | H16: 21.802611 | I16: ANGULO | J16: =IF(I16="SUSPENSION",0,IF(I16="TERMINAL",1,2)) -> 2 | K16: =1 -> 1 | L16: =1 -> 1 | M16: =J16*Parametros!$E$5*Parametros!$E$6 -> 12
A17: P011 | B17: 425462.53 | C17: 8436153.5 | D17: 3289.0418 | E17: 13 | F17: 1.9 | G17: 10.6 | H17: 57.411798 | I17: ANCLAJE | J17: =IF(I17="SUSPENSION",0,IF(I17="TERMINAL",1,2)) -> 2 | K17: =1 -> 1 | L17: =1 -> 1 | M17: =J17*Parametros!$E$5*Parametros!$E$6 -> 12
A18: P012 | B18: 425481.52 | C18: 8436095.5 | D18: 3292.781 | E18: 13 | F18: 1.9 | G18: 10.6 | H18: 23.894066 | I18: ANGULO | J18: =IF(I18="SUSPENSION",0,IF(I18="TERMINAL",1,2)) -> 2 | K18: =1 -> 1 | L18: =1 -> 1 | M18: =J18*Parametros!$E$5*Parametros!$E$6 -> 12
... A117: P111 | B117: 423945.21 | C117: 8430951.9 | D117: 3760.8973 | E117: 13 | F117: 1.9 | G117: 10.6 | H117: 0 | I117: TERMINAL | J117: =IF(I117="SUSPENSION",0,IF(I117="TERMINAL",1,2)) -> 1 | K117: =1 -> 1 | L117: =1 -> 1 | M117: =J117*Parametros!$E$5*Parametros!$E$6 -> 6

Sheet Vanos
A2: LONGITUD DE CONDUCTOR POR CATENARIA EDS
A6: Vano | B6: Inicial | C6: Final | D6: L horiz. (m) | E6: Δz amarre (m) | F6: H EDS (N) | G6: q (N/m) | H6: a = H/q (m) | I6: u (–) | J6: x0 (m) | K6: u0 (–) | L6: u1 (–) | M6: Cable/fase (m) | N6: Terna (m)
A7: V001 | B7: P001 | C7: P002 | D7: =SQRT((INDEX(Postes!$B$7:$B$117,MATCH(C7,Postes!$A$7:$A$117,0))-INDEX(Postes!$B$7:$B$117,MATCH(B7,Postes!$A$7:$A$117,0)))^2+(INDEX(Postes!$C$7:$C$117,MATCH(C7,Postes!$A$7:$A$117,0))-INDEX(Postes!$C$7:$C$117,MATCH(B7,Postes!$A$7:$A$117,0)))^2) -> 47.146597 | E7: =INDEX(Postes!$D$7:$D$117,MATCH(C7,Postes!$A$7:$A$117,0))+INDEX(Postes!$G$7:$G$117,MATCH(C7,Postes!$A$7:$A$117,0))-INDEX(Postes!$D$7:$D$117,MATCH(B7,Postes!$A$7:$A$117,0))-INDEX(Postes!$G$7:$G$117,MATCH(B7,Postes!$A$7:$A$117,0)) -> 14.315387 | F7: =Parametros!$E$8*Parametros!$E$9 -> 2205 | G7: =Parametros!$E$10/1000*Parametros!$E$11 -> 1.3238977 | H7: =F7/G7 -> 1665.5365 | I7: =ASINH(E7/(2*H7*SINH(D7/(2*H7)))) -> 0.2991439 | J7: =D7/2-H7*I7 -> -474.66178 | K7: =-J7/H7 -> 0.28499032 | L7: =(D7-J7)/H7 -> 0.31329748 | M7: =H7*(SINH(L7)-SINH(K7)) -> 49.273525 | N7: =M7*Parametros!$E$5 -> 147.82058
A8: V002 | B8: P002 | C8: P003 | D8: =SQRT((INDEX(Postes!$B$7:$B$117,MATCH(C8,Postes!$A$7:$A$117,0))-INDEX(Postes!$B$7:$B$117,MATCH(B8,Postes!$A$7:$A$117,0)))^2+(INDEX(Postes!$C$7:$C$117,MATCH(C8,Postes!$A$7:$A$117,0))-INDEX(Postes!$C$7:$C$117,MATCH(B8,Postes!$A$7:$A$117,0)))^2) -> 47.146597 | E8: =INDEX(Postes!$D$7:$D$117,MATCH(C8,Postes!$A$7:$A$117,0))+INDEX(Postes!$G$7:$G$117,MATCH(C8,Postes!$A$7:$A$117,0))-INDEX(Postes!$D$7:$D$117,MATCH(B8,Postes!$A$7:$A$117,0))-INDEX(Postes!$G$7:$G$117,MATCH(B8,Postes!$A$7:$A$117,0)) -> 13.265247 | F8: =Parametros!$E$8*Parametros!$E$9 -> 2205 | G8: =Parametros!$E$10/1000*Parametros!$E$11 -> 1.3238977 | H8: =F8/G8 -> 1665.5365 | I8: =ASINH(E8/(2*H8*SINH(D8/(2*H8)))) -> 0.2777667 | J8: =D8/2-H8*I8 -> -439.05727 | K8: =-J8/H8 -> 0.26361312 | L8: =(D8-J8)/H8 -> 0.29192028 | M8: =H8*(SINH(L8)-SINH(K8)) -> 48.978738 | N8: =M8*Parametros!$E$5 -> 146.93621
A9: V003 | B9: P003 | C9: P004 | D9: =SQRT((INDEX(Postes!$B$7:$B$117,MATCH(C9,Postes!$A$7:$A$117,0))-INDEX(Postes!$B$7:$B$117,MATCH(B9,Postes!$A$7:$A$117,0)))^2+(INDEX(Postes!$C$7:$C$117,MATCH(C9,Postes!$A$7:$A$117,0))-INDEX(Postes!$C$7:$C$117,MATCH(B9,Postes!$A$7:$A$117,0)))^2) -> 75.564649 | E9: =INDEX(Postes!$D$7:$D$117,MATCH(C9,Postes!$A$7:$A$117,0))+INDEX(Postes!$G$7:$G$117,MATCH(C9,Postes!$A$7:$A$117,0))-INDEX(Postes!$D$7:$D$117,MATCH(B9,Postes!$A$7:$A$117,0))-INDEX(Postes!$G$7:$G$117,MATCH(B9,Postes!$A$7:$A$117,0)) -> 0.013907941 | F9: =Parametros!$E$8*Parametros!$E$9 -> 2205 | G9: =Parametros!$E$10/1000*Parametros!$E$11 -> 1.3238977 | H9: =F9/G9 -> 1665.5365 | I9: =ASINH(E9/(2*H9*SINH(D9/(2*H9)))) -> 0.00018403775 | J9: =D9/2-H9*I9 -> 37.475803 | K9: =-J9/H9 -> -0.02250074 | L9: =(D9-J9)/H9 -> 0.022868815 | M9: =H9*(SINH(L9)-SINH(K9)) -> 75.571131 | N9: =M9*Parametros!$E$5 -> 226.71339
A10: V004 | B10: P004 | C10: P005 | D10: =SQRT((INDEX(Postes!$B$7:$B$117,MATCH(C10,Postes!$A$7:$A$117,0))-INDEX(Postes!$B$7:$B$117,MATCH(B10,Postes!$A$7:$A$117,0)))^2+(INDEX(Postes!$C$7:$C$117,MATCH(C10,Postes!$A$7:$A$117,0))-INDEX(Postes!$C$7:$C$117,MATCH(B10,Postes!$A$7:$A$117,0)))^2) -> 75.564649 | E10: =INDEX(Postes!$D$7:$D$117,MATCH(C10,Postes!$A$7:$A$117,0))+INDEX(Postes!$G$7:$G$117,MATCH(C10,Postes!$A$7:$A$117,0))-INDEX(Postes!$D$7:$D$117,MATCH(B10,Postes!$A$7:$A$117,0))-INDEX(Postes!$G$7:$G$117,MATCH(B10,Postes!$A$7:$A$117,0)) -> -0.98642692 | F10: =Parametros!$E$8*Parametros!$E$9 -> 2205 | G10: =Parametros!$E$10/1000*Parametros!$E$11 -> 1.3238977 | H10: =F10/G10 -> 1665.5365 | I10: =ASINH(E10/(2*H10*SINH(D10/(2*H10)))) -> -0.013052589 | J10: =D10/2-H10*I10 -> 59.521888 | K10: =-J10/H10 -> -0.035737367 | L10: =(D10-J10)/H10 -> 0.0096321884 | M10: =H10*(SINH(L10)-SINH(K10)) -> 75.577568 | N10: =M10*Parametros!$E$5 -> 226.7327
A11: V005 | B11: P005 | C11: P006 | D11: =SQRT((INDEX(Postes!$B$7:$B$117,MATCH(C11,Postes!$A$7:$A$117,0))-INDEX(Postes!$B$7:$B$117,MATCH(B11,Postes!$A$7:$A$117,0)))^2+(INDEX(Postes!$C$7:$C$117,MATCH(C11,Postes!$A$7:$A$117,0))-INDEX(Postes!$C$7:$C$117,MATCH(B11,Postes!$A$7:$A$117,0)))^2) -> 71.024548 | E11: =INDEX(Postes!$D$7:$D$117,MATCH(C11,Postes!$A$7:$A$117,0))+INDEX(Postes!$G$7:$G$117,MATCH(C11,Postes!$A$7:$A$117,0))-INDEX(Postes!$D$7:$D$117,MATCH(B11,Postes!$A$7:$A$117,0))-INDEX(Postes!$G$7:$G$117,MATCH(B11,Postes!$A$7:$A$117,0)) -> 7.3940343 | F11: =Parametros!$E$8*Parametros!$E$9 -> 2205 | G11: =Parametros!$E$10/1000*Parametros!$E$11 -> 1.3238977 | H11: =F11/G11 -> 1665.5365 | I11: =ASINH(E11/(2*H11*SINH(D11/(2*H11)))) -> 0.10391035 | J11: =D11/2-H11*I11 -> -137.55421 | K11: =-J11/H11 -> 0.082588528 | L11: =(D11-J11)/H11 -> 0.12523217 | M11: =H11*(SINH(L11)-SINH(K11)) -> 71.413743 | N11: =M11*Parametros!$E$5 -> 214.24123
A12: V006 | B12: P006 | C12: P007 | D12: =SQRT((INDEX(Postes!$B$7:$B$117,MATCH(C12,Postes!$A$7:$A$117,0))-INDEX(Postes!$B$7:$B$117,MATCH(B12,Postes!$A$7:$A$117,0)))^2+(INDEX(Postes!$C$7:$C$117,MATCH(C12,Postes!$A$7:$A$117,0))-INDEX(Postes!$C$7:$C$117,MATCH(B12,Postes!$A$7:$A$117,0)))^2) -> 71.024549 | E12: =INDEX(Postes!$D$7:$D$117,MATCH(C12,Postes!$A$7:$A$117,0))+INDEX(Postes!$G$7:$G$117,MATCH(C12,Postes!$A$7:$A$117,0))-INDEX(Postes!$D$7:$D$117,MATCH(B12,Postes!$A$7:$A$117,0))-INDEX(Postes!$G$7:$G$117,MATCH(B12,Postes!$A$7:$A$117,0)) -> 2.5916616 | F12: =Parametros!$E$8*Parametros!$E$9 -> 2205 | G12: =Parametros!$E$10/1000*Parametros!$E$11 -> 1.3238977 | H12: =F12/G12 -> 1665.5365 | I12: =ASINH(E12/(2*H12*SINH(D12/(2*H12)))) -> 0.036478804 | J12: =D12/2-H12*I12 -> -25.244505 | K12: =-J12/H12 -> 0.015156981 | L12: =(D12-J12)/H12 -> 0.057800627 | M12: =H12*(SINH(L12)-SINH(K12)) -> 71.077195 | N12: =M12*Parametros!$E$5 -> 213.23159
A13: V007 | B13: P007 | C13: P008 | D13: =SQRT((INDEX(Postes!$B$7:$B$117,MATCH(C13,Postes!$A$7:$A$117,0))-INDEX(Postes!$B$7:$B$117,MATCH(B13,Postes!$A$7:$A$117,0)))^2+(INDEX(Postes!$C$7:$C$117,MATCH(C13,Postes!$A$7:$A$117,0))-INDEX(Postes!$C$7:$C$117,MATCH(B13,Postes!$A$7:$A$117,0)))^2) -> 57.507392 | E13: =INDEX(Postes!$D$7:$D$117,MATCH(C13,Postes!$A$7:$A$117,0))+INDEX(Postes!$G$7:$G$117,MATCH(C13,Postes!$A$7:$A$117,0))-INDEX(Postes!$D$7:$D$117,MATCH(B13,Postes!$A$7:$A$117,0))-INDEX(Postes!$G$7:$G$117,MATCH(B13,Postes!$A$7:$A$117,0)) -> -1.5050179 | F13: =Parametros!$E$8*Parametros!$E$9 -> 2205 | G13: =Parametros!$E$10/1000*Parametros!$E$11 -> 1.3238977 | H13: =F13/G13 -> 1665.5365 | I13: =ASINH(E13/(2*H13*SINH(D13/(2*H13)))) -> -0.026166574 | J13: =D13/2-H13*I13 -> 72.33508 | K13: =-J13/H13 -> -0.043430499 | L13: =(D13-J13)/H13 -> -0.0089026499 | M13: =H13*(SINH(L13)-SINH(K13)) -> 57.529938 | N13: =M13*Parametros!$E$5 -> 172.58981
A14: V008 | B14: P008 | C14: P009 | D14: =SQRT((INDEX(Postes!$B$7:$B$117,MATCH(C14,Postes!$A$7:$A$117,0))-INDEX(Postes!$B$7:$B$117,MATCH(B14,Postes!$A$7:$A$117,0)))^2+(INDEX(Postes!$C$7:$C$117,MATCH(C14,Postes!$A$7:$A$117,0))-INDEX(Postes!$C$7:$C$117,MATCH(B14,Postes!$A$7:$A$117,0)))^2) -> 70.11432 | E14: =INDEX(Postes!$D$7:$D$117,MATCH(C14,Postes!$A$7:$A$117,0))+INDEX(Postes!$G$7:$G$117,MATCH(C14,Postes!$A$7:$A$117,0))-INDEX(Postes!$D$7:$D$117,MATCH(B14,Postes!$A$7:$A$117,0))-INDEX(Postes!$G$7:$G$117,MATCH(B14,Postes!$A$7:$A$117,0)) -> 1.8540142 | F14: =Parametros!$E$8*Parametros!$E$9 -> 2205 | G14: =Parametros!$E$10/1000*Parametros!$E$11 -> 1.3238977 | H14: =F14/G14 -> 1665.5365 | I14: =ASINH(E14/(2*H14*SINH(D14/(2*H14)))) -> 0.0264377 | J14: =D14/2-H14*I14 -> -8.9757931 | K14: =-J14/H14 -> 0.0053891303 | L14: =(D14-J14)/H14 -> 0.047486269 | M14: =H14*(SINH(L14)-SINH(K14)) -> 70.144004 | N14: =M14*Parametros!$E$5 -> 210.43201
A15: V009 | B15: P009 | C15: P010 | D15: =SQRT((INDEX(Postes!$B$7:$B$117,MATCH(C15,Postes!$A$7:$A$117,0))-INDEX(Postes!$B$7:$B$117,MATCH(B15,Postes!$A$7:$A$117,0)))^2+(INDEX(Postes!$C$7:$C$117,MATCH(C15,Postes!$A$7:$A$117,0))-INDEX(Postes!$C$7:$C$117,MATCH(B15,Postes!$A$7:$A$117,0)))^2) -> 70.11432 | E15: =INDEX(Postes!$D$7:$D$117,MATCH(C15,Postes!$A$7:$A$117,0))+INDEX(Postes!$G$7:$G$117,MATCH(C15,Postes!$A$7:$A$117,0))-INDEX(Postes!$D$7:$D$117,MATCH(B15,Postes!$A$7:$A$117,0))-INDEX(Postes!$G$7:$G$117,MATCH(B15,Postes!$A$7:$A$117,0)) -> 6.2928294 | F15: =Parametros!$E$8*Parametros!$E$9 -> 2205 | G15: =Parametros!$E$10/1000*Parametros!$E$11 -> 1.3238977 | H15: =F15/G15 -> 1665.5365 | I15: =ASINH(E15/(2*H15*SINH(D15/(2*H15)))) -> 0.089624326 | J15: =D15/2-H15*I15 -> -114.21543 | K15: =-J15/H15 -> 0.068575757 | L15: =(D15-J15)/H15 -> 0.1106729 | M15: =H15*(SINH(L15)-SINH(K15)) -> 70.401304 | N15: =M15*Parametros!$E$5 -> 211.20391
A16: V010 | B16: P010 | C16: P011 | D16: =SQRT((INDEX(Postes!$B$7:$B$117,MATCH(C16,Postes!$A$7:$A$117,0))-INDEX(Postes!$B$7:$B$117,MATCH(B16,Postes!$A$7:$A$117,0)))^2+(INDEX(Postes!$C$7:$C$117,MATCH(C16,Postes!$A$7:$A$117,0))-INDEX(Postes!$C$7:$C$117,MATCH(B16,Postes!$A$7:$A$117,0)))^2) -> 50.214197 | E16: =INDEX(Postes!$D$7:$D$117,MATCH(C16,Postes!$A$7:$A$117,0))+INDEX(Postes!$G$7:$G$117,MATCH(C16,Postes!$A$7:$A$117,0))-INDEX(Postes!$D$7:$D$117,MATCH(B16,Postes!$A$7:$A$117,0))-INDEX(Postes!$G$7:$G$117,MATCH(B16,Postes!$A$7:$A$117,0)) -> 10.480952 | F16: =Parametros!$E$8*Parametros!$E$9 -> 2205 | G16: =Parametros!$E$10/1000*Parametros!$E$11 -> 1.3238977 | H16: =F16/G16 -> 1665.5365 | I16: =ASINH(E16/(2*H16*SINH(D16/(2*H16)))) -> 0.20723055 | J16: =D16/2-H16*I16 -> -320.04294 | K16: =-J16/H16 -> 0.19215606 | L16: =(D16-J16)/H16 -> 0.22230503 | M16: =H16*(SINH(L16)-SINH(K16)) -> 51.298215 | N16: =M16*Parametros!$E$5 -> 153.89465
A17: V011 | B17: P011 | C17: P012 | D17: =SQRT((INDEX(Postes!$B$7:$B$117,MATCH(C17,Postes!$A$7:$A$117,0))-INDEX(Postes!$B$7:$B$117,MATCH(B17,Postes!$A$7:$A$117,0)))^2+(INDEX(Postes!$C$7:$C$117,MATCH(C17,Postes!$A$7:$A$117,0))-INDEX(Postes!$C$7:$C$117,MATCH(B17,Postes!$A$7:$A$117,0)))^2) -> 60.968945 | E17: =INDEX(Postes!$D$7:$D$117,MATCH(C17,Postes!$A$7:$A$117,0))+INDEX(Postes!$G$7:$G$117,MATCH(C17,Postes!$A$7:$A$117,0))-INDEX(Postes!$D$7:$D$117,MATCH(B17,Postes!$A$7:$A$117,0))-INDEX(Postes!$G$7:$G$117,MATCH(B17,Postes!$A$7:$A$117,0)) -> 3.7392304 | F17: =Parametros!$E$8*Parametros!$E$9 -> 2205 | G17: =Parametros!$E$10/1000*Parametros!$E$11 -> 1.3238977 | H17: =F17/G17 -> 1665.5365 | I17: =ASINH(E17/(2*H17*SINH(D17/(2*H17)))) -> 0.061288282 | J17: =D17/2-H17*I17 -> -71.593396 | K17: =-J17/H17 -> 0.042985187 | L17: =(D17-J17)/H17 -> 0.079591377 | M17: =H17*(SINH(L17)-SINH(K17)) -> 61.086899 | N17: =M17*Parametros!$E$5 -> 183.2607
A18: V012 | B18: P012 | C18: P013 | D18: =SQRT((INDEX(Postes!$B$7:$B$117,MATCH(C18,Postes!$A$7:$A$117,0))-INDEX(Postes!$B$7:$B$117,MATCH(B18,Postes!$A$7:$A$117,0)))^2+(INDEX(Postes!$C$7:$C$117,MATCH(C18,Postes!$A$7:$A$117,0))-INDEX(Postes!$C$7:$C$117,MATCH(B18,Postes!$A$7:$A$117,0)))^2) -> 54.308189 | E18: =INDEX(Postes!$D$7:$D$117,MATCH(C18,Postes!$A$7:$A$117,0))+INDEX(Postes!$G$7:$G$117,MATCH(C18,Postes!$A$7:$A$117,0))-INDEX(Postes!$D$7:$D$117,MATCH(B18,Postes!$A$7:$A$117,0))-INDEX(Postes!$G$7:$G$117,MATCH(B18,Postes!$A$7:$A$117,0)) -> 3.5496813 | F18: =Parametros!$E$8*Parametros!$E$9 -> 2205 | G18: =Parametros!$E$10/1000*Parametros!$E$11 -> 1.3238977 | H18: =F18/G18 -> 1665.5365 | I18: =ASINH(E18/(2*H18*SINH(D18/(2*H18)))) -> 0.065312466 | J18: =D18/2-H18*I18 -> -81.626201 | K18: =-J18/H18 -> 0.049008954 | L18: =(D18-J18)/H18 -> 0.081615979 | M18: =H18*(SINH(L18)-SINH(K18)) -> 54.426473 | N18: =M18*Parametros!$E$5 -> 163.27942
