Workbook

Sheet LEER
A1: Hoja / modelo | B1: Alcance y estado
A2: Flujo exacto | B2: Valores iterativos calculados por Python; ver residuo y CSV.
A3: Verificacion_linea | B3: Fórmulas aproximadas editables; no sustituyen flujo con TX.
A4: Poste13m | B4: Comparación de flexión tipo; capacidad axial/suelo pendientes.
A5: Tendido | B5: Estados por vano; no tabla autorizada para montaje.
A6: Tensiones | B6: Decisión definitiva pendiente; fuentes/tomas son sensibilidades.

Sheet Parametros
A1: Parametro | B1: Valor | C1: Unidad | D1: Fuente / estado
A2: P | B2: 171.486 | C2: kW | D2: Demanda de estudio
A3: FP | B3: 0.9 | C3: pu | D3: Supuesto
A4: R75 | B4: 5.4325691 | C4: ohm/fase | D4: Longitud física EDS
A5: X | B5: 3.0914667 | C5: ohm/fase | D5: DMG/GMR aproximado
A6: Longitud | B6: 6758.1203 | C6: m | D6: Catenaria EDS de gabinete

Sheet Verificacion_linea
A1: V nominal kV | B1: P kW | C1: FP | D1: I aproximada A | E1: R ohm/fase | F1: X ohm/fase | G1: Caida aprox V | H1: Caida aprox % | I1: Perdida aprox kW | J1: Nota
A2: 10 | B2: =Parametros!B2 | C2: =Parametros!B3 | D2: =B2/(SQRT(3)*A2*C2) | E2: =Parametros!B4 | F2: =Parametros!B5 | G2: =SQRT(3)*D2*(E2*C2+F2*SQRT(1-C2^2)) | H2: =G2/(A2*1000)*100 | I2: =3*D2^2*E2/1000 | J2: PQ fijo; comparar con origen_MT_fijo exacto
A3: 20 | B3: =Parametros!B2 | C3: =Parametros!B3 | D3: =B3/(SQRT(3)*A3*C3) | E3: =Parametros!B4 | F3: =Parametros!B5 | G3: =SQRT(3)*D3*(E3*C3+F3*SQRT(1-C3^2)) | H3: =G3/(A3*1000)*100 | I3: =3*D3^2*E3/1000 | J3: PQ fijo; comparar con origen_MT_fijo exacto
A4: 22 | B4: =Parametros!B2 | C4: =Parametros!B3 | D4: =B4/(SQRT(3)*A4*C4) | E4: =Parametros!B4 | F4: =Parametros!B5 | G4: =SQRT(3)*D4*(E4*C4+F4*SQRT(1-C4^2)) | H4: =G4/(A4*1000)*100 | I4: =3*D4^2*E4/1000 | J4: PQ fijo; comparar con origen_MT_fijo exacto
A5: 22.9 | B5: =Parametros!B2 | C5: =Parametros!B3 | D5: =B5/(SQRT(3)*A5*C5) | E5: =Parametros!B4 | F5: =Parametros!B5 | G5: =SQRT(3)*D5*(E5*C5+F5*SQRT(1-C5^2)) | H5: =G5/(A5*1000)*100 | I5: =3*D5^2*E5/1000 | J5: PQ fijo; comparar con origen_MT_fijo exacto

Sheet Poste13m
A1: Parametro / paso | B1: Valor / formula | C1: Unidad | D1: Estado
A2: Longitud | B2: 13 | C2: m | D2: tipo
A3: Empotramiento | B3: 1.9 | C3: m | D3: hipótesis
A4: Carga transversal | B4: 400 | C4: daN | D4: ficha referencia13/400
A5: Distancia carga a cima | B5: 0.15 | C5: m | D5: referenciaRD018; ensayo por confirmar
A6: Factor rotura | B6: 2 | C6: - | D6: exigir certificado
A7: Phi resistencia | B7: 0.65 | C7: - | D7: gradoB de estudio
A8: Brazo | B8: =B2-B3-B5 | C8: m | D8: calculado
A9: Momento servicio | B9: =B4*10*B8/1000 | C9: kNm | D9: no capacidad axial
A10: Momento reducido | B10: =B9*B6*B7 | C10: kNm | D10: comparar con cargas factorizadas
A11: Peso terna85m | B11: =3*0.135*85 | C11: kg | D11: sólo cable sin hielo
A12: Tracción ternaEDS | B12: =3*2205 | C12: N | D12: terminal sin factores
A13: Componente angular30deg | B13: =3*2*2205*SIN(RADIANS(15)) | C13: N | D13: sin viento ni factores

Sheet comparacion_tensiones
A1: P_entrada_W | B1: Q_entrada_var | C1: residuo_balance_W | D1: residuo_balance_var | E1: iteraciones | F1: residuo_V | G1: kV | H1: toma_pu | I1: P_carga_kW | J1: FP | K1: MT_salida_kV | L1: MT_llegada_kV | M1: BT_llegada_V | N1: caida_linea_pct | O1: perdida_linea_kW | P1: P_generacion_kW | Q1: S_generador_kVA
A2: 179051.79 | B2: 109787.82 | C2: -5.3250642e-07 | D2: -6.3028347e-07 | E2: 27 | F2: 7.0522735e-09 | G2: 10 | H2: 1 | I2: 171.486 | J2: 0.9 | K2: 9.6603234 | L2: 9.5300968 | M2: 350.29108 | N2: 1.3480571 | O2: 2.3586331 | P2: 184.05179 | Q2: 214.30918
A3: 178672.24 | B3: 108550.36 | C3: -3.8531834e-07 | D3: -4.5625711e-07 | E3: 27 | F3: 5.015996e-09 | G3: 10 | H3: 1.025 | I3: 171.486 | J3: 0.9 | K3: 9.9212782 | L3: 9.7948183 | M3: 360.70926 | N3: 1.2746336 | O3: 2.224322 | P3: 183.67224 | Q3: 213.35105
A4: 178326.15 | B4: 107422 | C4: -7.6535434e-07 | D4: -9.0738467e-07 | E4: 26 | F4: 9.790118e-09 | G4: 10 | H4: 1.05 | I4: 171.486 | J4: 0.9 | K4: 10.181478 | L4: 10.058553 | M4: 371.06663 | N4: 1.2073367 | O4: 2.101854 | P4: 183.32615 | Q4: 212.4805
A5: 177172.42 | B5: 108314.05 | C5: -3.1243326e-07 | D5: -3.9572114e-07 | E5: 27 | F5: 8.1241437e-09 | G5: 20 | H5: 1 | I5: 171.486 | J5: 0.9 | K5: 19.329149 | L5: 19.264777 | M5: 354.31956 | N5: 0.33303008 | O5: 0.57632282 | P5: 182.17242 | Q5: 211.94038
A6: 176906.22 | B6: 107187.32 | C6: -2.3241046e-07 | D6: -2.940069e-07 | E6: 27 | F6: 5.9417769e-09 | G6: 20 | H6: 1.025 | I6: 171.486 | J6: 0.9 | K6: 19.850263 | L6: 19.787709 | M6: 364.60107 | N6: 0.31512891 | O6: 0.54426965 | P6: 181.90622 | Q6: 211.13738
A7: 176662.78 | B7: 106156.92 | C7: -1.7714592e-07 | D7: -2.2476524e-07 | E7: 27 | F7: 4.4433056e-09 | G7: 20 | H7: 1.05 | I7: 171.486 | J7: 0.9 | K7: 20.369969 | L7: 20.309125 | M7: 374.83206 | N7: 0.29869383 | O7: 0.51495685 | P7: 181.66278 | Q7: 210.40593
A8: 177066.33 | B8: 108231.02 | C8: -3.0319916e-07 | D8: -3.8562575e-07 | E8: 27 | F8: 8.6661185e-09 | G8: 22 | H8: 1 | I8: 171.486 | J8: 0.9 | K8: 21.262591 | L8: 21.204109 | M8: 354.54956 | N8: 0.27504582 | O8: 0.47568194 | P8: 182.06633 | Q8: 211.80676
A9: 176806.38 | B9: 107110.39 | C9: -2.2618042e-07 | D9: -2.881643e-07 | E9: 27 | F9: 6.350163e-09 | G9: 22 | H9: 1.025 | I9: 171.486 | J9: 0.9 | K9: 21.835768 | L9: 21.778936 | M9: 364.82346 | N9: 0.26027238 | O9: 0.44926127 | P9: 181.80638 | Q9: 211.01231
A10: 176568.62 | B10: 106085.4 | C10: -1.7226921e-07 | D10: -2.1923188e-07 | E10: 27 | F10: 4.7518404e-09 | G10: 22 | H10: 1.05 | I10: 171.486 | J10: 0.9 | K10: 22.407402 | L10: 22.352121 | M10: 375.0474 | N10: 0.24670761 | O10: 0.42509549 | P10: 181.56862 | Q10: 210.28855
A11: 177027.48 | B11: 108200.61 | C11: -2.9998955e-07 | D11: -3.8239523e-07 | E11: 27 | F11: 8.9166595e-09 | G11: 22.9 | H11: 1 | I11: 171.486 | J11: 0.9 | K11: 22.132625 | L11: 22.076455 | M11: 354.63388 | N11: 0.25378858 | O11: 0.43881804 | P11: 182.02748 | Q11: 211.75782
A12: 176769.81 | B12: 107082.22 | C12: -2.2376298e-07 | D12: -2.8522118e-07 | E12: 27 | F12: 6.5358898e-09 | G12: 22.9 | H12: 1.025 | I12: 171.486 | J12: 0.9 | K12: 22.729232 | L12: 22.674646 | M12: 364.90499 | N12: 0.24016061 | O12: 0.41445677 | P12: 181.76981 | Q12: 210.9665
A13: 176534.12 | B13: 106059.21 | C13: -1.7057209e-07 | D13: -2.1735104e-07 | E13: 27 | F13: 4.896091e-09 | G13: 22.9 | H13: 1.05 | I13: 171.486 | J13: 0.9 | K13: 23.324235 | L13: 23.271138 | M13: 375.12635 | N13: 0.22764718 | O13: 0.3921733 | P13: 181.53412 | Q13: 210.24555

Sheet origen_MT_fijo
A1: tension_origen_kV | B1: tension_llegada_kV | C1: I_A | D1: perdida_kW | E1: caida_pct | F1: residuo_W
A2: 10 | B2: 9.879713 | C2: 11.134769 | D2: 2.0206399 | E2: 1.2028701 | F2: -3.1550419e-06
A3: 20 | B3: 19.940404 | C3: 5.5168553 | D3: 0.496032 | E3: 0.2979823 | F3: -6.8196905e-06
A4: 22 | B4: 21.94585 | C4: 5.0127164 | D4: 0.4095178 | E4: 0.24613809 | F4: -6.6718905e-06
A5: 22.9 | B5: 22.847988 | C5: 4.8147925 | D5: 0.37781715 | E5: 0.22712779 | F5: -6.6146617e-06

Sheet demanda
A1: localidad | B1: viviendas_base | C1: usuarios_potenciales | D1: calificacion_kW | E1: simultaneidad | F1: demanda_kW | G1: estado
A2: Huancasayani Centro | B2: 95 | C2: 104 | D2: 0.6 | E2: 0.8 | F2: 49.92 | G2: HIPOTESIS DE MERCADO; SIN PADRON
A3: Huancasayani Bellavista | B3: 140 | C3: 154 | D3: 0.6 | E3: 0.8 | F3: 73.92 | G3: HIPOTESIS DE MERCADO; SIN PADRON
A4: Huancasayani Lince | B4: 86 | C4: 95 | D4: 0.4 | E4: 0.8 | F4: 30.4 | G4: HIPOTESIS DE MERCADO; SIN PADRON

Sheet estados_por_vano
A1: vano | B1: estado | C1: L_m | D1: dz_m | E1: H_N | F1: T_izq_N | G1: T_der_N | H1: T_RTS | I1: flecha_vertical_m | J1: longitud_cable_m | K1: separacion_perfil_heredado_m | L1: q_vertical_N_m | M1: q_viento_N_m | N1: residuo_longitud_m
A2: V001 | B2: EDS | C2: 47.146597 | D2: 14.315387 | E2: 2205 | F2: 2295.1522 | G2: 2314.1043 | H2: 0.15742206 | I2: 0.17434624 | J2: 49.273525 | K2: 9.6877899 | L2: 1.3238977 | M2: 0 | N2: 1.4210855e-14
A3: V001 | B3: VIENTO | C3: 47.146597 | D3: 14.315387 | E3: 3281.3244 | F3: 3291.0737 | G3: 3310.0258 | H3: 0.22517182 | I3: 0.12177832 | J3: 49.278185 | K3: 9.7193175 | L3: 1.3238977 | M3: 3.443895 | N3: -7.1054274e-15
A4: V001 | B4: HIELO | C4: 47.146597 | D4: 14.315387 | E4: 3439.8223 | F4: 3568.517 | G4: 3623.709 | H4: 0.24651082 | I4: 0.32547585 | J4: 49.277268 | K4: 9.597051 | L4: 3.8554322 | M4: 0 | N4: 0
A5: V001 | B5: COMBINADO | C5: 47.146597 | D5: 14.315387 | E5: 3344.7188 | F5: 3436.1141 | G5: 3469.5622 | H5: 0.23602464 | I5: 0.20539792 | J5: 49.274971 | K5: 9.6691573 | L5: 2.3365115 | M5: 1.4349562 | N5: -6.3948846e-14
A6: V001 | B6: FRIO | C6: 47.146597 | D6: 14.315387 | E6: 3500.7675 | F6: 3649.2514 | G6: 3668.2035 | H6: 0.24953765 | I6: 0.10981313 | J6: 49.272617 | K6: 9.7264932 | L6: 1.3238977 | M6: 0 | N6: -5.6843419e-14
A7: V001 | B7: CALOR_FINAL | C7: 47.146597 | D7: 14.315387 | E7: 363.16545 | F7: 371.42406 | G7: 390.37617 | H7: 0.026556202 | I7: 1.0590899 | J7: 49.327568 | K7: 9.1439989 | L7: 1.3238977 | M7: 0 | N7: 0
A8: V002 | B8: EDS | C8: 47.146597 | D8: 13.265247 | E8: 2205 | F8: 2282.0595 | G8: 2299.6213 | H8: 0.15643683 | I8: 0.17330319 | J8: 48.978738 | K8: 10.462205 | L8: 1.3238977 | M8: 0 | N8: -2.8421709e-14
A9: V002 | B9: VIENTO | C9: 47.146597 | D9: 13.265247 | E9: 3268.3777 | F9: 3276.3808 | G9: 3293.9426 | H9: 0.22407773 | I9: 0.12088899 | J9: 48.983344 | K9: 10.462205 | L9: 1.3238977 | M9: 3.443895 | N9: 7.1054274e-15
A10: V002 | B10: HIELO | C10: 47.146597 | D10: 13.265247 | E10: 3448.3936 | F10: 3557.9313 | G10: 3609.0746 | H10: 0.24551528 | I10: 0.3227247 | J10: 48.982477 | K10: 10.462205 | L10: 3.8554322 | M10: 0 | N10: 2.1316282e-14
A11: V002 | B11: COMBINADO | C11: 47.146597 | D11: 13.265247 | E11: 3345.3173 | F11: 3423.2858 | G11: 3454.2802 | H11: 0.23498505 | I11: 0.203777 | J11: 48.980171 | K11: 10.462205 | L11: 2.3365115 | M11: 1.4349562 | N11: 0
A12: V002 | B12: FRIO | C12: 47.146597 | D12: 13.265247 | E12: 3507.7708 | F12: 3635.3317 | G12: 3652.8935 | H12: 0.24849616 | I12: 0.1089382 | J12: 48.977822 | K12: 10.462205 | L12: 1.3238977 | M12: 0 | N12: 1.4921397e-13
A13: V002 | B13: CALOR_FINAL | C13: 47.146597 | D13: 13.265247 | E13: 364.60414 | F13: 371.33459 | G13: 388.89642 | H13: 0.026455539 | I13: 1.0486092 | J13: 49.032665 | K13: 10.332649 | L13: 1.3238977 | M13: 0 | N13: -2.8421709e-14
... A661: V110 | B661: CALOR_FINAL | C661: 19.701947 | D661: 0.96862762 | E661: 163.08872 | F661: 163.16646 | G661: 164.44883 | H661: 0.011186995 | I661: 0.39456026 | J661: 19.746722 | K661: 10.394712 | L661: 1.3238977 | M661: 0 | N661: 0

Sheet fuerzas_por_apoyo
A1: poste | B1: estado | C1: viento_az_deg | D1: F_E_kN | E1: F_N_kN | F1: vertical_conductores_herrajes_kN | G1: compresion_con_retenidas_kN | H1: M_sin_retenidas_kNm | I1: M_con_retenidas_ideales_kNm | J1: tiro_max_retenida_kN | K1: M_viento_poste_kNm
A2: P001 | B2: EDS | C2: 0 | D2: 6.981844 | E2: -8.3896139 | F2: -2.7175337 | G2: 8.1972163 | H2: 115.69635 | I2: 2.1557135e-14 | J2: 15.435787 | K2: 0
A3: P001 | B3: VIENTO | C3: 0 | D3: 10.010172 | E3: -11.264613 | F3: -3.9766464 | G3: 11.085101 | H3: 169.27592 | I3: 18.165153 | J3: 21.300528 | K3: 13.878875
A4: P001 | B4: VIENTO | C4: 15 | D4: 10.290473 | E4: -11.462877 | F4: -4.0773545 | G4: 11.316089 | H4: 170.01873 | I4: 19.603711 | J4: 21.769617 | K4: 13.878875
A5: P001 | B5: VIENTO | C5: 30 | D5: 10.453811 | E5: -11.582108 | F5: -4.1369028 | G5: 11.452671 | H5: 168.8312 | I5: 20.455409 | J5: 22.046986 | K5: 13.878875
A6: P001 | B6: VIENTO | C6: 45 | D6: 10.475929 | E6: -11.598417 | F6: -4.1450045 | G6: 11.471253 | H6: 165.5448 | I6: 20.571388 | J6: 22.084723 | K6: 13.878875
A7: P001 | B7: VIENTO | C7: 60 | D7: 10.353727 | E7: -11.508782 | F7: -4.1003527 | G7: 11.368838 | H7: 160.34498 | I7: 19.932502 | J7: 21.87674 | K7: 13.878875
A8: P001 | B8: VIENTO | C8: 75 | D8: 10.104872 | E8: -11.330524 | F8: -4.0104205 | G8: 11.162567 | H8: 153.75207 | I8: 18.647478 | J8: 21.457844 | K8: 13.878875
A9: P001 | B9: VIENTO | C9: 90 | D9: 9.7698556 | E9: -11.104053 | F9: -3.8925032 | G9: 10.892107 | H9: 146.64315 | I9: 16.962944 | J9: 20.908597 | K9: 13.878875
A10: P001 | B10: VIENTO | C10: 105 | D10: 9.414346 | E10: -10.89626 | F10: -3.7749649 | G10: 10.622516 | H10: 140.27721 | I10: 15.278048 | J10: 20.361113 | K10: 13.878875
A11: P001 | B11: VIENTO | C11: 120 | D11: 9.1232156 | E11: -10.794171 | F11: -3.6945987 | G11: 10.438185 | H11: 136.17473 | I11: 14.117814 | J11: 19.986774 | K11: 13.878875
A12: P001 | B12: VIENTO | C12: 135 | D12: 8.9711568 | E12: -10.870668 | F12: -3.6829192 | G12: 10.411396 | H12: 135.59175 | I12: 13.948352 | J12: 19.932372 | K12: 13.878875
A13: P001 | B13: VIENTO | C13: 150 | D13: 8.9775574 | E13: -11.131408 | F13: -3.745012 | G13: 10.553815 | H13: 138.72843 | I13: 14.846673 | J13: 20.221595 | K13: 13.878875
... A5773: P111 | B5773: CALOR_FINAL | C5773: 0 | D5773: 0.2945763 | E5773: 0.75162532 | F5773: 0.54858743 | G5773: 1.3558766 | H5773: 8.5572653 | I5773: 1.3473209e-15 | J5773: 1.1416793 | K5773: 0

Sheet balance_fuente
A1: kV | B1: oferta_hipotetica_kW | C1: reserva_limbani_kW | D1: necesidad_kW | E1: margen_kW | F1: estado
A2: 10 | B2: 150 | C2: 0 | D2: 183.32615 | E2: -33.326151 | F2: NO CONFIRMA DISPONIBILIDAD HIDRICA
A3: 10 | B3: 150 | C3: 25 | D3: 208.32615 | E3: -58.326151 | F3: NO CONFIRMA DISPONIBILIDAD HIDRICA
A4: 10 | B4: 150 | C4: 50 | D4: 233.32615 | E4: -83.326151 | F4: NO CONFIRMA DISPONIBILIDAD HIDRICA
A5: 10 | B5: 200 | C5: 0 | D5: 183.32615 | E5: 16.673849 | F5: NO CONFIRMA DISPONIBILIDAD HIDRICA
A6: 10 | B6: 200 | C6: 25 | D6: 208.32615 | E6: -8.3261509 | F6: NO CONFIRMA DISPONIBILIDAD HIDRICA
A7: 10 | B7: 200 | C7: 50 | D7: 233.32615 | E7: -33.326151 | F7: NO CONFIRMA DISPONIBILIDAD HIDRICA
A8: 22.9 | B8: 150 | C8: 0 | D8: 181.53412 | E8: -31.534118 | F8: NO CONFIRMA DISPONIBILIDAD HIDRICA
A9: 22.9 | B9: 150 | C9: 25 | D9: 206.53412 | E9: -56.534118 | F9: NO CONFIRMA DISPONIBILIDAD HIDRICA
A10: 22.9 | B10: 150 | C10: 50 | D10: 231.53412 | E10: -81.534118 | F10: NO CONFIRMA DISPONIBILIDAD HIDRICA
A11: 22.9 | B11: 200 | C11: 0 | D11: 181.53412 | E11: 18.465882 | F11: NO CONFIRMA DISPONIBILIDAD HIDRICA
A12: 22.9 | B12: 200 | C12: 25 | D12: 206.53412 | E12: -6.5341179 | F12: NO CONFIRMA DISPONIBILIDAD HIDRICA
A13: 22.9 | B13: 200 | C13: 50 | D13: 231.53412 | E13: -31.534118 | F13: NO CONFIRMA DISPONIBILIDAD HIDRICA

Sheet energia
A1: kV | B1: fraccion_pico | C1: horas_hipotesis | D1: P_carga_kW | E1: perdida_linea_kW | F1: energia_perdida_linea_kWh | G1: estado
A2: 10 | B2: 0.25 | C2: 2920 | D2: 42.8715 | E2: 0.12333565 | F2: 360.14009 | G2: CURVA SINTETICA, REEMPLAZAR CON MEDICIONES
A3: 10 | B3: 0.5 | C3: 2920 | D3: 85.743 | E3: 0.4944573 | F3: 1443.8153 | G3: CURVA SINTETICA, REEMPLAZAR CON MEDICIONES
A4: 10 | B4: 0.75 | C4: 2190 | D4: 128.6145 | E4: 1.1421012 | F4: 2501.2017 | G4: CURVA SINTETICA, REEMPLAZAR CON MEDICIONES
A5: 10 | B5: 1 | C5: 730 | D5: 171.486 | E5: 2.101854 | F5: 1534.3534 | G5: CURVA SINTETICA, REEMPLAZAR CON MEDICIONES
A6: 22.9 | B6: 0.25 | C6: 2920 | D6: 42.8715 | E6: 0.023407827 | F6: 68.350856 | G6: CURVA SINTETICA, REEMPLAZAR CON MEDICIONES
A7: 22.9 | B7: 0.5 | C7: 2920 | D7: 85.743 | E7: 0.093369708 | F7: 272.63955 | G7: CURVA SINTETICA, REEMPLAZAR CON MEDICIONES
A8: 22.9 | B8: 0.75 | C8: 2190 | D8: 128.6145 | E8: 0.21445531 | F8: 469.65713 | G8: CURVA SINTETICA, REEMPLAZAR CON MEDICIONES
A9: 22.9 | B9: 1 | C9: 730 | D9: 171.486 | E9: 0.3921733 | F9: 286.28651 | G9: CURVA SINTETICA, REEMPLAZAR CON MEDICIONES

Sheet cortocircuito
A1: kV | B1: estado | C1: punto | D1: Ik3_A | E1: impedancia_referida_MT_ohm | F1: estado_datos
A2: 10 | B2: SUBTRANSITORIO | C2: MT_SALIDA | D2: 55.359938 | E2: 104.29027 | F2: HIPOTESIS DE PLACA Y MODELO SIMPLIFICADO; NO AJUSTE RELE
A3: 10 | B3: SUBTRANSITORIO | C3: MT_LLEGADA | D3: 53.384805 | E3: 108.1488 | F3: HIPOTESIS DE PLACA Y MODELO SIMPLIFICADO; NO AJUSTE RELE
A4: 10 | B4: SUBTRANSITORIO | C4: BT_LLEGADA | D4: 1149.8399 | E4: 132.13516 | F4: HIPOTESIS DE PLACA Y MODELO SIMPLIFICADO; NO AJUSTE RELE
A5: 10 | B5: TRANSITORIO | C5: MT_SALIDA | D5: 40.075403 | E5: 144.06599 | F5: HIPOTESIS DE PLACA Y MODELO SIMPLIFICADO; NO AJUSTE RELE
A6: 10 | B6: TRANSITORIO | C6: MT_LLEGADA | D6: 39.083351 | E6: 147.72282 | F6: HIPOTESIS DE PLACA Y MODELO SIMPLIFICADO; NO AJUSTE RELE
A7: 10 | B7: TRANSITORIO | C7: BT_LLEGADA | D7: 885.13405 | E7: 171.65115 | F7: HIPOTESIS DE PLACA Y MODELO SIMPLIFICADO; NO AJUSTE RELE
A8: 10 | B8: SOSTENIDO | C8: MT_SALIDA | D8: 7.7643127 | E8: 743.59482 | F8: HIPOTESIS DE PLACA Y MODELO SIMPLIFICADO; NO AJUSTE RELE
A9: 10 | B9: SOSTENIDO | C9: MT_LLEGADA | D9: 7.7309905 | E9: 746.79987 | F9: HIPOTESIS DE PLACA Y MODELO SIMPLIFICADO; NO AJUSTE RELE
A10: 10 | B10: SOSTENIDO | C10: BT_LLEGADA | D10: 197.21244 | E10: 770.40923 | F10: HIPOTESIS DE PLACA Y MODELO SIMPLIFICADO; NO AJUSTE RELE
A11: 22.9 | B11: SUBTRANSITORIO | C11: MT_SALIDA | D11: 24.174645 | E11: 546.90859 | F11: HIPOTESIS DE PLACA Y MODELO SIMPLIFICADO; NO AJUSTE RELE
A12: 22.9 | B12: SUBTRANSITORIO | C12: MT_LLEGADA | D12: 24.009346 | E12: 550.67395 | F12: HIPOTESIS DE PLACA Y MODELO SIMPLIFICADO; NO AJUSTE RELE
A13: 22.9 | B13: SUBTRANSITORIO | C13: BT_LLEGADA | D13: 1178.2043 | E13: 676.24824 | F13: HIPOTESIS DE PLACA Y MODELO SIMPLIFICADO; NO AJUSTE RELE
... A19: 22.9 | B19: SOSTENIDO | C19: BT_LLEGADA | D19: 197.8859 | E19: 4026.3534 | F19: HIPOTESIS DE PLACA Y MODELO SIMPLIFICADO; NO AJUSTE RELE

Sheet vanos_limite_ejemplo
A1: poste | B1: vano_limite_ejemplo_m | C1: primer_vano_que_falla_m | D1: restriccion | E1: M_resistente_tipo_kNm | F1: estado
A2: 13m/400daN | B2: 128 | C2: 129 | D2: FLECHA/GALIBO DE ESTUDIO | E2: 56.94 | F2: TERRENO PLANO, DOS VANOS IGUALES, 15% RTS; NO ES VANO AUTORIZADO
A3: 13m/600daN | B3: 128 | C3: 129 | D3: FLECHA/GALIBO DE ESTUDIO | E3: 85.41 | F3: TERRENO PLANO, DOS VANOS IGUALES, 15% RTS; NO ES VANO AUTORIZADO

Sheet postes
A1: id | B1: e | C1: n | D1: cota_dem_m | E1: progresiva_m | F1: poste_m | G1: empotramiento_estudio_m | H1: amarre_m | I1: angulo_deg | J1: tipo_r01 | K1: tipo_r02 | L1: retenidas_r01 | M1: retenidas_r02 | N1: M_sin_retenidas_kNm | O1: M_con_ideales_kNm | P1: M_capacidad_tipo_kNm | Q1: DC_r01_recalculado | R1: DC_propuesta | S1: vertical_min_kN | T1: vertical_max_kN | U1: compresion_retenidas_max_kN | V1: retenida_tiro_kN | W1: retenida_rotura_min_kN | X1: caso_sin_retenidas | Y1: viento_critico_deg | Z1: acciones | AA1: capacidad_axial_kN | AB1: validacion | AC1: DC_poste_13m_400dan_tipo | AD1: anclajes_con_alerta
A2: P001 | B2: 425715 | C2: 8436650 | D2: 3235.3252 | E2: 0 | F2: 13 | G2: 1.9 | H2: 10.6 | I2: 0 | J2: TERMINAL | K2: TERMINAL | L2: 1 | M2: 1 | N2: 183.68527 | O2: 20.571388 | P2: 85.41 | Q2: 0.24085456 | R2: 0.24085456 | S2: -4.6649958 | T2: 0.049878232 | U2: 12.733453 | V2: 24.506623 | W2: 60 | X2: FRIO | Y2: 0 | Z2: CARGA ASCENDENTE; COMPROBAR FIJACION Y HERREJES | AB2: PENDIENTE: AXIAL/FLEXION, SUELO, HERRAJES Y TOPOGRAFIA | AC2: 0.36128184 | AD2: 0
A3: P002 | B3: 425745.16 | C3: 8436613.8 | D3: 3249.6406 | E3: 47.146597 | F3: 13 | G3: 1.9 | H3: 10.6 | I3: 0 | J3: SUSPENSION | K3: SUSPENSION | L3: 0 | M3: 0 | N3: 27.257459 | O3: 27.246357 | P3: 85.41 | Q3: 0.31913663 | R3: 0.31913663 | S3: 0.78112393 | T3: 1.6697818 | V3: 0 | W3: 0 | X3: VIENTO | Y3: 225 | Z3: CONSERVAR COMO CANDIDATO; CONFIRMAR CAMPO Y CERTIFICADOS | AB3: PENDIENTE: AXIAL/FLEXION, SUELO, HERRAJES Y TOPOGRAFIA | AC3: 0.47870494 | AD3: 0
A4: P003 | B4: 425775.32 | C4: 8436577.5 | D4: 3261.1058 | E4: 94.293193 | F4: 15 | G4: 2.1 | H4: 12.4 | I4: 92.594134 | J4: ANCLAJE | K4: ANCLAJE | L4: 2 | M4: 2 | N4: 320.33695 | O4: 30.918951 | P4: 99.45 | Q4: 0.31089945 | R4: 0.31089945 | S4: 1.3298384 | T4: 6.3308724 | U4: 42.034118 | V4: 26.352028 | W4: 60 | X4: HIELO | Y4: 0 | Z4: REPLANTEAR GIRO MAYOR DE 90 GRADOS O ARMADO ESPECIAL | AB4: PENDIENTE: AXIAL/FLEXION, SUELO, HERRAJES Y TOPOGRAFIA | AD4: 0
A5: P004 | B5: 425715.11 | C5: 8436531.9 | D5: 3261.1198 | E5: 169.85784 | F5: 15 | G5: 2.1 | H5: 12.4 | I5: 0 | J5: SUSPENSION | K5: SUSPENSION | L5: 0 | M5: 0 | N5: 42.71534 | O5: 42.715155 | P5: 99.45 | Q5: 0.42951573 | R5: 0.42951573 | S5: 0.93830087 | T5: 2.008165 | V5: 0 | W5: 0 | X5: VIENTO | Y5: 120 | Z5: CONSERVAR COMO CANDIDATO; CONFIRMAR CAMPO Y CERTIFICADOS | AB5: PENDIENTE: AXIAL/FLEXION, SUELO, HERRAJES Y TOPOGRAFIA | AD5: 0
A6: P005 | B6: 425654.89 | C6: 8436486.2 | D6: 3260.1333 | E6: 245.42249 | F6: 15 | G6: 2.1 | H6: 12.4 | I6: 14.059956 | J6: ANGULO | K6: ANGULO | L6: 2 | M6: 2 | N6: 93.672 | O6: 41.956841 | P6: 99.45 | Q6: 0.4218888 | R6: 0.4218888 | S6: -1.1249486 | T6: 0.57280952 | U6: 36.575732 | V6: 26.350939 | W6: 60 | X6: VIENTO | Y6: 315 | Z6: CARGA ASCENDENTE; COMPROBAR FIJACION Y HERREJES | AB6: PENDIENTE: AXIAL/FLEXION, SUELO, HERRAJES Y TOPOGRAFIA | AD6: 0
A7: P006 | B7: 425610.42 | C7: 8436430.8 | D7: 3265.7274 | E7: 316.44704 | F7: 17 | G7: 2.1 | H7: 14.2 | I7: 1.2074183e-06 | J7: SUSPENSION | K7: SUSPENSION | L7: 0 | M7: 0 | N7: 51.085756 | O7: 51.073567 | P7: 115.05 | Q7: 0.44403091 | R7: 0.44403091 | S7: 1.0555594 | T7: 2.9276593 | V7: 0 | W7: 0 | X7: VIENTO | Y7: 315 | Z7: CONSERVAR COMO CANDIDATO; CONFIRMAR CAMPO Y CERTIFICADOS | AB7: PENDIENTE: AXIAL/FLEXION, SUELO, HERRAJES Y TOPOGRAFIA | AD7: 0
A8: P007 | B8: 425565.95 | C8: 8436375.4 | D8: 3270.119 | E8: 387.47159 | F8: 15 | G8: 2.1 | H8: 12.4 | I8: 7.8217251 | J8: ANGULO | K8: ANGULO | L8: 2 | M8: 2 | N8: 67.806186 | O8: 39.155608 | P8: 99.45 | Q8: 0.39372155 | R8: 0.39372155 | S8: 0.98969135 | T8: 2.7039411 | U8: 38.916839 | V8: 26.044122 | W8: 60 | X8: VIENTO | Y8: 330 | Z8: CONSERVAR COMO CANDIDATO; CONFIRMAR CAMPO Y CERTIFICADOS | AB8: PENDIENTE: AXIAL/FLEXION, SUELO, HERRAJES Y TOPOGRAFIA | AD8: 0
A9: P008 | B9: 425536.38 | C9: 8436326.1 | D9: 3270.414 | E9: 444.97898 | F9: 13 | G9: 1.9 | H9: 10.6 | I9: 13.486932 | J9: ANGULO | K9: ANGULO | L9: 2 | M9: 2 | N9: 72.427548 | O9: 30.961064 | P9: 85.41 | Q9: 0.36249928 | R9: 0.36249928 | S9: -0.081600517 | T9: 0.70235633 | U9: 36.778961 | V9: 25.988112 | W9: 60 | X9: VIENTO | Y9: 330 | Z9: CARGA ASCENDENTE; COMPROBAR FIJACION Y HERREJES | AB9: PENDIENTE: AXIAL/FLEXION, SUELO, HERRAJES Y TOPOGRAFIA | AC9: 0.54374892 | AD9: 0
A10: P009 | B10: 425515.34 | C10: 8436259.2 | D10: 3272.268 | E10: 515.0933 | F10: 13 | G10: 1.9 | H10: 10.6 | I10: 0 | J10: SUSPENSION | K10: ANCLAJE_PROPUESTO | L10: 0 | M10: 2 | N10: 33.096641 | O10: 33.094101 | P10: 85.41 | Q10: 0.38750312 | R10: 0.38747337 | S10: -0.22040643 | T10: 0.7016784 | U10: 37.229155 | V10: 25.988112 | W10: 60 | X10: VIENTO | Y10: 345 | Z10: PROPONER RETENCION Y RETENIDAS; VERIFICAR ARMADO; CARGA ASCENDENTE; COMPROBAR FIJACION Y HERREJES | AB10: PENDIENTE: AXIAL/FLEXION, SUELO, HERRAJES Y TOPOGRAFIA | AC10: 0.58121006 | AD10: 0
A11: P010 | B11: 425494.31 | C11: 8436192.4 | D11: 3278.5608 | E11: 585.20762 | F11: 13 | G11: 1.9 | H11: 10.6 | I11: 21.802611 | J11: ANGULO | K11: ANGULO | L11: 2 | M11: 2 | N11: 95.812904 | O11: 29.918061 | P11: 85.41 | Q11: 0.35028756 | R11: 0.35028756 | S11: -1.2796622 | T11: 0.64604571 | U11: 35.198858 | V11: 25.942883 | W11: 60 | X11: VIENTO | Y11: 150 | Z11: CARGA ASCENDENTE; COMPROBAR FIJACION Y HERREJES | AB11: PENDIENTE: AXIAL/FLEXION, SUELO, HERRAJES Y TOPOGRAFIA | AC11: 0.52543134 | AD11: 0
A12: P011 | B12: 425462.53 | C12: 8436153.5 | D12: 3289.0418 | E12: 635.42182 | F12: 13 | G12: 1.9 | H12: 10.6 | I12: 57.411798 | J12: ANCLAJE | K12: ANCLAJE | L12: 2 | M12: 2 | N12: 185.86184 | O12: 25.660444 | P12: 85.41 | Q12: 0.3004384 | R12: 0.3004384 | S12: 1.0460695 | T12: 3.9396023 | U12: 39.197887 | V12: 25.373042 | W12: 60 | X12: VIENTO | Y12: 0 | Z12: CONSERVAR COMO CANDIDATO; CONFIRMAR CAMPO Y CERTIFICADOS | AB12: PENDIENTE: AXIAL/FLEXION, SUELO, HERRAJES Y TOPOGRAFIA | AC12: 0.4506576 | AD12: 0
A13: P012 | B13: 425481.52 | C13: 8436095.5 | D13: 3292.781 | E13: 696.39076 | F13: 13 | G13: 1.9 | H13: 10.6 | I13: 23.894066 | J13: ANGULO | K13: ANGULO | L13: 2 | M13: 2 | N13: 99.887481 | O13: 28.859966 | P13: 85.41 | Q13: 0.33789914 | R13: 0.33789914 | S13: 0.68548095 | T13: 1.3995932 | U13: 36.980746 | V13: 25.373042 | W13: 60 | X13: VIENTO | Y13: 180 | Z13: CONSERVAR COMO CANDIDATO; CONFIRMAR CAMPO Y CERTIFICADOS | AB13: PENDIENTE: AXIAL/FLEXION, SUELO, HERRAJES Y TOPOGRAFIA | AC13: 0.50684872 | AD13: 0
A14: P013 | B14: 425476.09 | C14: 8436041.5 | D14: 3296.3307 | E14: 750.69895 | F14: 13 | G14: 1.9 | H14: 10.6 | I14: 68.6119 | J14: ANCLAJE | K14: ANCLAJE | L14: 2 | M14: 2 | N14: 208.47566 | O14: 22.966294 | P14: 85.41 | Q14: 0.26889467 | R14: 0.26889467 | S14: -3.2677848 | T14: 0.41963177 | U14: 31.88106 | V14: 24.946306 | W14: 60 | X14: FRIO | Y14: 0 | Z14: CARGA ASCENDENTE; COMPROBAR FIJACION Y HERREJES | AB14: PENDIENTE: AXIAL/FLEXION, SUELO, HERRAJES Y TOPOGRAFIA | AC14: 0.403342 | AD14: 0
A15: P014 | B15: 425437.9 | C15: 8436030.8 | D15: 3308.0455 | E15: 790.35985 | F15: 13 | G15: 1.9 | H15: 10.6 | I15: 53.191938 | J15: ANCLAJE | K15: ANCLAJE | L15: 2 | M15: 2 | N15: 176.82808 | O15: 26.559158 | P15: 85.41 | Q15: 0.31096075 | R15: 0.31096075 | S15: 0.77707624 | T15: 3.1990895 | U15: 38.284733 | V15: 25.919668 | W15: 60 | X15: VIENTO | Y15: 315 | Z15: CONSERVAR COMO CANDIDATO; CONFIRMAR CAMPO Y CERTIFICADOS | AB15: PENDIENTE: AXIAL/FLEXION, SUELO, HERRAJES Y TOPOGRAFIA | AC15: 0.46644112 | AD15: 0
A16: P015 | B16: 425411.97 | C16: 8435963.8 | D16: 3318.7524 | E16: 862.18507 | F16: 15 | G16: 2.1 | H16: 12.4 | I16: 0 | J16: SUSPENSION | K16: SUSPENSION | L16: 0 | M16: 0 | N16: 41.913695 | O16: 41.9084 | P16: 99.45 | Q16: 0.42145495 | R16: 0.42145495 | S16: 0.92753422 | T16: 2.0101462 | V16: 0 | W16: 0 | X16: VIENTO | Y16: 165 | Z16: CONSERVAR COMO CANDIDATO; CONFIRMAR CAMPO Y CERTIFICADOS | AB16: PENDIENTE: AXIAL/FLEXION, SUELO, HERRAJES Y TOPOGRAFIA | AD16: 0
A17: P016 | B17: 425386.04 | C17: 8435896.9 | D17: 3330.0829 | E17: 934.01029 | F17: 15 | G17: 2.1 | H17: 12.4 | I17: 0 | J17: SUSPENSION | K17: SUSPENSION | L17: 0 | M17: 0 | N17: 41.793231 | O17: 41.773206 | P17: 99.45 | Q17: 0.42024365 | R17: 0.42024365 | S17: 1.0992584 | T17: 3.1933467 | V17: 0 | W17: 0 | X17: VIENTO | Y17: 165 | Z17: CONSERVAR COMO CANDIDATO; CONFIRMAR CAMPO Y CERTIFICADOS | AB17: PENDIENTE: AXIAL/FLEXION, SUELO, HERRAJES Y TOPOGRAFIA | AD17: 0
A18: P017 | B18: 425360.11 | C18: 8435829.9 | D18: 3337.3697 | E18: 1005.8355 | F18: 13 | G18: 1.9 | H18: 10.6 | I18: 25.926747 | J18: ANGULO | K18: ANGULO | L18: 2 | M18: 2 | N18: 107.52699 | O18: 29.497214 | P18: 85.41 | Q18: 0.3453602 | R18: 0.3453602 | S18: 0.92373117 | T18: 2.0591224 | U18: 37.8724 | V18: 26.068853 | W18: 60 | X18: VIENTO | Y18: 345 | Z18: CONSERVAR COMO CANDIDATO; CONFIRMAR CAMPO Y CERTIFICADOS | AB18: PENDIENTE: AXIAL/FLEXION, SUELO, HERRAJES Y TOPOGRAFIA | AC18: 0.51804029 | AD18: 0
A19: P018 | B19: 425364.11 | C19: 8435781.9 | D19: 3339.7054 | E19: 1054.0019 | F19: 13 | G19: 1.9 | H19: 10.6 | I19: 0.55819507 | J19: SUSPENSION | K19: SUSPENSION | L19: 0 | M19: 0 | N19: 28.657291 | O19: 27.020815 | P19: 85.41 | Q19: 0.33552617 | R19: 0.33552617 | S19: 0.098025595 | T19: 0.66932279 | V19: 0 | W19: 0 | X19: VIENTO | Y19: 180 | Z19: CONSERVAR COMO CANDIDATO; CONFIRMAR CAMPO Y CERTIFICADOS | AB19: PENDIENTE: AXIAL/FLEXION, SUELO, HERRAJES Y TOPOGRAFIA | AC19: 0.50328926 | AD19: 0
A20: P019 | B20: 425367.63 | C20: 8435734 | D20: 3343.7868 | E20: 1102.0483 | F20: 13 | G20: 1.9 | H20: 10.6 | I20: 26.825312 | J20: ANGULO | K20: ANGULO | L20: 2 | M20: 2 | N20: 98.810086 | O20: 23.543648 | P20: 85.41 | Q20: 0.27565446 | R20: 0.27565446 | S20: -1.0996513 | T20: 0.63960766 | U20: 34.145214 | V20: 25.019145 | W20: 60 | X20: VIENTO | Y20: 180 | Z20: CARGA ASCENDENTE; COMPROBAR FIJACION Y HERREJES; REPLANTEAR ANCLAJES CON CONFLICTO CARTOGRAFICO | AB20: PENDIENTE: AXIAL/FLEXION, SUELO, HERRAJES Y TOPOGRAFIA | AC20: 0.4134817 | AD20: 1
A21: P020 | B21: 425357.63 | C21: 8435710 | D21: 3348.5825 | E21: 1128.0483 | F21: 13 | G21: 1.9 | H21: 10.6 | I21: 13.873703 | J21: ANGULO | K21: ANGULO | L21: 2 | M21: 2 | N21: 59.043731 | O21: 21.015499 | P21: 85.41 | Q21: 0.24605431 | R21: 0.24605431 | S21: 0.68316731 | T21: 2.120935 | U21: 37.361511 | V21: 25.115505 | W21: 60 | X21: VIENTO | Y21: 345 | Z21: CONSERVAR COMO CANDIDATO; CONFIRMAR CAMPO Y CERTIFICADOS | AB21: PENDIENTE: AXIAL/FLEXION, SUELO, HERRAJES Y TOPOGRAFIA | AC21: 0.36908147 | AD21: 0
A22: P021 | B22: 425353.63 | C22: 8435684 | D22: 3351.4854 | E22: 1154.3542 | F22: 13 | G22: 1.9 | H22: 10.6 | I22: 7.500798 | J22: ANGULO | K22: ANGULO | L22: 2 | M22: 2 | N22: 50.215805 | O22: 25.952236 | P22: 85.41 | Q22: 0.30385477 | R22: 0.30385477 | S22: -0.58080057 | T22: 0.41509431 | U22: 34.636444 | V22: 25.23691 | W22: 60 | X22: VIENTO | Y22: 345 | Z22: CARGA ASCENDENTE; COMPROBAR FIJACION Y HERREJES | AB22: PENDIENTE: AXIAL/FLEXION, SUELO, HERRAJES Y TOPOGRAFIA | AC22: 0.45578216 | AD22: 0
A23: P022 | B23: 425352.3 | C23: 8435622.6 | D23: 3362.4579 | E23: 1215.702 | F23: 13 | G23: 1.9 | H23: 10.6 | I23: 0 | J23: SUSPENSION | K23: SUSPENSION | L23: 0 | M23: 0 | N23: 30.899635 | O23: 30.897317 | P23: 85.41 | Q23: 0.36178006 | R23: 0.36178006 | S23: 0.89403193 | T23: 2.0919089 | V23: 0 | W23: 0 | X23: VIENTO | Y23: 180 | Z23: CONSERVAR COMO CANDIDATO; CONFIRMAR CAMPO Y CERTIFICADOS | AB23: PENDIENTE: AXIAL/FLEXION, SUELO, HERRAJES Y TOPOGRAFIA | AC23: 0.54267009 | AD23: 0
A24: P023 | B24: 425350.96 | C24: 8435561.3 | D24: 3369.674 | E24: 1277.0498 | F24: 15 | G24: 2.1 | H24: 12.4 | I24: 0 | J24: SUSPENSION | K24: SUSPENSION | L24: 0 | M24: 0 | N24: 38.676336 | O24: 38.67407 | P24: 99.45 | Q24: 0.38890232 | R24: 0.38890232 | S24: 0.35989145 | T24: 1.0548381 | V24: 0 | W24: 0 | X24: VIENTO | Y24: 0 | Z24: CONSERVAR COMO CANDIDATO; CONFIRMAR CAMPO Y CERTIFICADOS | AB24: PENDIENTE: AXIAL/FLEXION, SUELO, HERRAJES Y TOPOGRAFIA | AD24: 0
A25: P024 | B25: 425349.63 | C25: 8435500 | D25: 3378.5335 | E25: 1338.3977 | F25: 17 | G25: 2.1 | H25: 14.2 | I25: 4.3817226 | J25: SUSPENSION | K25: SUSPENSION | L25: 0 | M25: 0 | N25: 68.765378 | O25: 49.968449 | P25: 115.05 | Q25: 0.59769994 | R25: 0.59769994 | S25: 1.339225 | T25: 5.2642585 | V25: 0 | W25: 0 | X25: VIENTO | Y25: 0 | Z25: CONSERVAR COMO CANDIDATO; CONFIRMAR CAMPO Y CERTIFICADOS | AB25: PENDIENTE: AXIAL/FLEXION, SUELO, HERRAJES Y TOPOGRAFIA | AD25: 0
A26: P025 | B26: 425353.63 | C26: 8435427 | D26: 3376.4163 | E26: 1411.5072 | F26: 17 | G26: 2.1 | H26: 14.2 | I26: 1.2074183e-06 | J26: SUSPENSION | K26: SUSPENSION | L26: 0 | M26: 0 | N26: 51.931785 | O26: 51.931526 | P26: 115.05 | Q26: 0.45138448 | R26: 0.45138448 | S26: 0.038072715 | T26: 0.80471589 | V26: 0 | W26: 0 | X26: VIENTO | Y26: 0 | Z26: CONSERVAR COMO CANDIDATO; CONFIRMAR CAMPO Y CERTIFICADOS | AB26: PENDIENTE: AXIAL/FLEXION, SUELO, HERRAJES Y TOPOGRAFIA | AD26: 0
A27: P026 | B27: 425357.63 | C27: 8435354 | D27: 3379.7079 | E27: 1484.6167 | F27: 15 | G27: 2.1 | H27: 12.4 | I27: 1.2074183e-06 | J27: SUSPENSION | K27: ANCLAJE_PROPUESTO | L27: 0 | M27: 2 | N27: 42.201679 | O27: 42.197296 | P27: 99.45 | Q27: 0.42435071 | R27: 0.42430665 | S27: -0.36664205 | T27: 0.68654663 | U27: 37.368797 | V27: 26.187294 | W27: 60 | X27: VIENTO | Y27: 180 | Z27: PROPONER RETENCION Y RETENIDAS; VERIFICAR ARMADO; CARGA ASCENDENTE; COMPROBAR FIJACION Y HERREJES | AB27: PENDIENTE: AXIAL/FLEXION, SUELO, HERRAJES Y TOPOGRAFIA | AD27: 0
A28: P027 | B28: 425361.63 | C28: 8435281 | D28: 3386.5424 | E28: 1557.7262 | F28: 15 | G28: 2.1 | H28: 12.4 | I28: 1.2074183e-06 | J28: SUSPENSION | K28: SUSPENSION | L28: 0 | M28: 0 | N28: 42.272756 | O28: 42.270855 | P28: 99.45 | Q28: 0.42506542 | R28: 0.42506542 | S28: 0.57242208 | T28: 1.3862593 | V28: 0 | W28: 0 | X28: VIENTO | Y28: 180 | Z28: CONSERVAR COMO CANDIDATO; CONFIRMAR CAMPO Y CERTIFICADOS | AB28: PENDIENTE: AXIAL/FLEXION, SUELO, HERRAJES Y TOPOGRAFIA | AD28: 0
A29: P028 | B29: 425365.63 | C29: 8435208 | D29: 3394.7255 | E29: 1630.8357 | F29: 15 | G29: 2.1 | H29: 12.4 | I29: 15.142466 | J29: ANGULO | K29: ANGULO | L29: 2 | M29: 2 | N29: 94.298071 | O29: 39.629017 | P29: 99.45 | Q29: 0.39848182 | R29: 0.39848182 | S29: 0.94857663 | T29: 2.0628661 | U29: 38.36167 | V29: 26.111696 | W29: 60 | X29: VIENTO | Y29: 180 | Z29: CONSERVAR COMO CANDIDATO; CONFIRMAR CAMPO Y CERTIFICADOS | AB29: PENDIENTE: AXIAL/FLEXION, SUELO, HERRAJES Y TOPOGRAFIA | AD29: 0
A30: P029 | B30: 425353.35 | C30: 8435150.2 | D30: 3401.8413 | E30: 1689.8483 | F30: 13 | G30: 1.9 | H30: 10.6 | I30: 3.8760055 | J30: SUSPENSION | K30: ANCLAJE_PROPUESTO | L30: 0 | M30: 2 | N30: 40.624643 | O30: 23.942003 | P30: 85.41 | Q30: 0.4756427 | R30: 0.2803185 | S30: -1.9513661 | T30: 0.73828182 | U30: 33.126865 | V30: 25.222564 | W30: 60 | X30: VIENTO | Y30: 0 | Z30: PROPONER RETENCION Y RETENIDAS; VERIFICAR ARMADO; CARGA ASCENDENTE; COMPROBAR FIJACION Y HERREJES | AB30: PENDIENTE: AXIAL/FLEXION, SUELO, HERRAJES Y TOPOGRAFIA | AC30: 0.42047775 | AD30: 0
A31: P030 | B31: 425351.35 | C31: 8435136.2 | D31: 3403.3906 | E31: 1703.9904 | F31: 15 | G31: 2.1 | H31: 12.4 | I31: 6.0309424 | J31: ANGULO | K31: ANGULO | L31: 2 | M31: 2 | N31: 66.570382 | O31: 34.227835 | P31: 99.45 | Q31: 0.3441713 | R31: 0.3441713 | S31: 0.57472293 | T31: 3.2425016 | U31: 38.252943 | V31: 26.705835 | W31: 60 | X31: VIENTO | Y31: 345 | Z31: CONSERVAR COMO CANDIDATO; CONFIRMAR CAMPO Y CERTIFICADOS | AB31: PENDIENTE: AXIAL/FLEXION, SUELO, HERRAJES Y TOPOGRAFIA | AD31: 0
A32: P031 | B32: 425348.35 | C32: 8435054.4 | D32: 3409.713 | E32: 1785.8926 | F32: 17 | G32: 2.1 | H32: 14.2 | I32: 0 | J32: SUSPENSION | K32: SUSPENSION | L32: 0 | M32: 0 | N32: 55.284808 | O32: 55.282038 | P32: 115.05 | Q32: 0.48052853 | R32: 0.48052853 | S32: 1.0793932 | T32: 2.7451416 | V32: 0 | W32: 0 | X32: VIENTO | Y32: 180 | Z32: CONSERVAR COMO CANDIDATO; CONFIRMAR CAMPO Y CERTIFICADOS | AB32: PENDIENTE: AXIAL/FLEXION, SUELO, HERRAJES Y TOPOGRAFIA | AD32: 0
A33: P032 | B33: 425345.35 | C33: 8434972.5 | D33: 3415.8596 | E33: 1867.7948 | F33: 15 | G33: 2.1 | H33: 12.4 | I33: 5.4619308 | J33: ANGULO | K33: ANGULO | L33: 2 | M33: 2 | N33: 64.254369 | O33: 43.648387 | P33: 99.45 | Q33: 0.43889781 | R33: 0.43889781 | S33: 0.72435996 | T33: 1.6265987 | U33: 39.060387 | V33: 26.751791 | W33: 60 | X33: VIENTO | Y33: 0 | Z33: CONSERVAR COMO CANDIDATO; CONFIRMAR CAMPO Y CERTIFICADOS | AB33: PENDIENTE: AXIAL/FLEXION, SUELO, HERRAJES Y TOPOGRAFIA | AD33: 0
A34: P033 | B34: 425349.66 | C34: 8434899.2 | D34: 3420.5315 | E34: 1941.2546 | F34: 15 | G34: 2.1 | H34: 12.4 | I34: 1.2074183e-06 | J34: SUSPENSION | K34: SUSPENSION | L34: 0 | M34: 0 | N34: 42.341582 | O34: 42.337792 | P34: 99.45 | Q34: 0.42575748 | R34: 0.42575748 | S34: 0.18873907 | T34: 0.97457091 | V34: 0 | W34: 0 | X34: VIENTO | Y34: 180 | Z34: CONSERVAR COMO CANDIDATO; CONFIRMAR CAMPO Y CERTIFICADOS | AB34: PENDIENTE: AXIAL/FLEXION, SUELO, HERRAJES Y TOPOGRAFIA | AD34: 0
A35: P034 | B35: 425353.97 | C35: 8434825.9 | D35: 3428.2097 | E35: 2014.7144 | F35: 15 | G35: 2.1 | H35: 12.4 | I35: 1.2074183e-06 | J35: SUSPENSION | K35: SUSPENSION | L35: 0 | M35: 0 | N35: 42.328242 | O35: 42.322009 | P35: 99.45 | Q35: 0.42562335 | R35: 0.42562335 | S35: 1.171192 | T35: 3.6195276 | V35: 0 | W35: 0 | X35: VIENTO | Y35: 0 | Z35: CONSERVAR COMO CANDIDATO; CONFIRMAR CAMPO Y CERTIFICADOS | AB35: PENDIENTE: AXIAL/FLEXION, SUELO, HERRAJES Y TOPOGRAFIA | AD35: 0
A36: P035 | B36: 425358.28 | C36: 8434752.5 | D36: 3430.1757 | E36: 2088.1743 | F36: 13 | G36: 1.9 | H36: 10.6 | I36: 152.53487 | J36: ANCLAJE | K36: ANCLAJE | L36: 2 | M36: 2 | N36: 358.56747 | O36: 26.846344 | P36: 85.41 | Q36: 0.31432319 | R36: 0.31432319 | S36: -4.4525887 | T36: 0.45754623 | U36: 31.307669 | V36: 26.213005 | W36: 60 | X36: HIELO | Y36: 0 | Z36: REPLANTEAR GIRO MAYOR DE 90 GRADOS O ARMADO ESPECIAL; CARGA ASCENDENTE; COMPROBAR FIJACION Y HERREJES | AB36: PENDIENTE: AXIAL/FLEXION, SUELO, HERRAJES Y TOPOGRAFIA | AC36: 0.47148478 | AD36: 0
A37: P036 | B37: 425345.5 | C37: 8434774 | D37: 3437.6292 | E37: 2113.1187 | F37: 13 | G37: 1.9 | H37: 10.6 | I37: 51.799556 | J37: ANCLAJE | K37: ANCLAJE | L37: 2 | M37: 2 | N37: 159.0617 | O37: 19.356065 | P37: 85.41 | Q37: 0.22662528 | R37: 0.22662528 | S37: -4.7360017 | T37: 0.42641447 | U37: 29.584529 | V37: 24.789745 | W37: 60 | X37: FRIO | Y37: 0 | Z37: CARGA ASCENDENTE; COMPROBAR FIJACION Y HERREJES | AB37: PENDIENTE: AXIAL/FLEXION, SUELO, HERRAJES Y TOPOGRAFIA | AC37: 0.33993792 | AD37: 0
A38: P037 | B38: 425325.66 | C38: 8434776.5 | D38: 3450.2242 | E38: 2133.124 | F38: 13 | G38: 1.9 | H38: 10.6 | I38: 48.713487 | J38: ANCLAJE | K38: ANCLAJE | L38: 2 | M38: 2 | N38: 146.0877 | O38: 20.764971 | P38: 85.41 | Q38: 0.24312107 | R38: 0.24312107 | S38: -0.37210146 | T38: 0.35437668 | U38: 33.332463 | V38: 23.746815 | W38: 60 | X38: FRIO | Y38: 0 | Z38: CARGA ASCENDENTE; COMPROBAR FIJACION Y HERREJES | AB38: PENDIENTE: AXIAL/FLEXION, SUELO, HERRAJES Y TOPOGRAFIA | AC38: 0.36468161 | AD38: 0
A39: P038 | B39: 425302.82 | C39: 8434756.4 | D39: 3470.8716 | E39: 2163.5411 | F39: 13 | G39: 1.9 | H39: 10.6 | I39: 41.939492 | J39: ANCLAJE | K39: ANCLAJE | L39: 2 | M39: 2 | N39: 147.93047 | O39: 27.53825 | P39: 85.41 | Q39: 0.32242419 | R39: 0.32242419 | S39: 1.4729791 | T39: 11.735626 | U39: 45.928349 | V39: 26.360157 | W39: 60 | X39: VIENTO | Y39: 345 | Z39: CONSERVAR COMO CANDIDATO; CONFIRMAR CAMPO Y CERTIFICADOS | AB39: PENDIENTE: AXIAL/FLEXION, SUELO, HERRAJES Y TOPOGRAFIA | AC39: 0.48363628 | AD39: 0
A40: P039 | B40: 425293.96 | C40: 8434681.2 | D40: 3468.7484 | E40: 2239.2656 | F40: 17 | G40: 2.1 | H40: 14.2 | I40: 10.231448 | J40: ANGULO | K40: ANGULO | L40: 2 | M40: 2 | N40: 97.852061 | O40: 53.947724 | P40: 115.05 | Q40: 0.46890677 | R40: 0.46890677 | S40: -0.44696217 | T40: 0.68179713 | U40: 37.894622 | V40: 26.739116 | W40: 60 | X40: VIENTO | Y40: 165 | Z40: CARGA ASCENDENTE; COMPROBAR FIJACION Y HERREJES | AB40: PENDIENTE: AXIAL/FLEXION, SUELO, HERRAJES Y TOPOGRAFIA | AD40: 0
...
