Workbook

Sheet Computadoras
A2: PCS. PORTÁTILES | F2: PCS DE ESCRITORIO
A4: Procesador | B4: Cantidad | C4: Carga (W/h) | D4: Carga Instalada W | F4: Procesador | G4: Cantidad | H4: Carga (W/h) | I4: Carga Instalada W | L4: cantidad PC | M4: carga W/h | N4: cantidad Impresoras | O4: carga W/h | P4: cantidad TV | Q4: carga W/h | T4: carga W/h | U4: Carga Instalada W
A5: Pentium | B5: 0 | C5: 300 | D5: =B5*C5 -> 0 | F5: Pentium | G5: 0 | H5: 300 | I5: =G5*H5 -> 0 | K5: zotano | L5: 35 | M5: 300 | N5: 5 | O5: 495 | P5: 1 | Q5: 180 | T5: 46 | U5: =T5*H5 -> 13800
A6: Pentium II | B6: 0 | C6: 300 | D6: =B6*C6 -> 0 | F6: Pentium II | G6: 0 | H6: 300 | I6: =G6*H6 -> 0 | K6: 1° nivel | T6: 83 | U6: =T6*H6 -> 24900
A7: Pentium III | B7: 0 | C7: 300 | D7: =B7*C7 -> 0 | F7: Pentium III | G7: 2 | H7: 300 | I7: =G7*H7 -> 600 | K7: 2° nivel | T7: 84 | U7: =T7*H7 -> 25200
A8: Pentium IV | B8: 0 | C8: 300 | D8: =B8*C8 -> 0 | F8: Pentium IV | G8: 19 | H8: 300 | I8: =G8*H8 -> 5700 | K8: 3° nivel | T8: 81 | U8: =T8*H8 -> 24300
A9: Celeron | B9: 0 | C9: 300 | D9: =B9*C9 -> 0 | F9: Celeron | G9: 6 | H9: 300 | I9: =G9*H9 -> 1800 | K9: 4° nivel | T9: 84 | U9: =T9*H9 -> 25200
A10: Pentium D | B10: 0 | C10: 300 | D10: =B10*C10 -> 0 | F10: Pentium D | G10: 7 | H10: 300 | I10: =G10*H10 -> 2100
A11: Dual Core | B11: 0 | C11: 300 | D11: =B11*C11 -> 0 | F11: Dual Core | G11: 2 | H11: 300 | I11: =G11*H11 -> 600
A12: Core 2 Duo | B12: 1 | C12: 300 | D12: =B12*C12 -> 300 | F12: Core 2 Duo | G12: 70 | H12: 300 | I12: =G12*H12 -> 21000
A13: Core 2 Quad | B13: 0 | C13: 300 | D13: =B13*C13 -> 0 | F13: Core 2 Quad | G13: 2 | H13: 300 | I13: =G13*H13 -> 600
A14: Core i3 | B14: 6 | C14: 300 | D14: =B14*C14 -> 1800 | F14: Core i3 | G14: 19 | H14: 300 | I14: =G14*H14 -> 5700
A15: Core i5 | B15: 3 | C15: 300 | D15: =B15*C15 -> 900 | F15: Core i5 | G15: 147 | H15: 300 | I15: =G15*H15 -> 44100
A16: Core i7 | B16: 22 | C16: 300 | D16: =B16*C16 -> 6600 | F16: Core i7 | G16: 37 | H16: 300 | I16: =G16*H16 -> 11100
A17: AMD | B17: 0 | C17: 300 | D17: =B17*C17 -> 0 | F17: AMD | G17: 65 | H17: 300 | I17: =G17*H17 -> 19500
A18: ATOM | B18: 0 | C18: 300 | D18: =B18*C18 -> 0 | F18: ATOM | G18: 2 | H18: 300 | I18: =G18*H18 -> 600
A19: TOTAL | B19: =SUM(B5:B18) -> 32 | C19: 300 | D19: =B19*C19 -> 9600 | F19: TOTAL | G19: =SUM(G5:G18) -> 378 | H19: 300 | I19: =G19*H19 -> 113400
F21: CARGA INSTALADA | G21: =D19+I19 -> 123000

Sheet CUADRO DE CARGAS
A1: CÁLCULO DE MÁXIMA DEMANDA
A2: ITEM | B2: DESCRIPCIÓN | C2: PORTENCIA | D2: CANTIDAD | E2: F.P. | F2: POTENCIA | G2: POTENCIA | H2: POTENCIA | I2: CORRIENTE | J2: FACTOR | K2: CORRIENTE | L2: CORRIENTE
C3: INSTALADA | F3: PARCIAL | G3: POR CIRCUITO | H3: TOTAL | I3: CALCULADA | J3: DISEÑO(FD) | K3: DISEÑO (Id) | L3: NOMINAL (In)
C4: (W) | D4: (UND) | F4: (W) | G4: (W) | H4: (W) | I4: (A) | J4: 0.8*P.T. | K4: 1.25xIn (A) | L4: (A)
A5: TG | B5: TABLERO GENERAL | H5: =H6+H16+H31+H40+H48+H56+H65+H67+H77+H87+H97+H106+H108+H111 -> 170829.92 | I5: =H5/(1.73*380*0.9) -> 288.72988 | J5: =0.8*H5 -> 136663.94 | K5: =1.25*L5 -> 324.82111 | L5: =H5/(1.73*380*1) -> 259.85689
A6: C-A | B6: SUB TABLERO GENERAL | H6: =SUM(H7:H15) -> 20273.92 | I6: =H6/(1.73*380*0.9) -> 34.266166 | J6: =0.6*H6 -> 12164.352 | K6: =1.25*L6 -> 38.549437 | L6: =H6/(1.73*380*1) -> 30.83955
A7: C-1 | B7: CIRCUITO DE BOMBA 1 | C7: =745.7 -> 745.7 | D7: 1 | E7: 0.8 | F7: =C7*D7*E7 -> 596.56 | G7: =F7 -> 596.56 | H7: =F7 -> 596.56 | I7: =G7/(220) -> 2.7116364 | J7: =0.8*H7 -> 477.248 | K7: =1.25*L7 -> 3.3895455 | L7: =H7/(1*220*1) -> 2.7116364
A8: C-2 | B8: CIRCUITO DE BOMBA 2 | C8: =745.7*1.5 -> 1118.55 | D8: 1 | E8: 0.8 | F8: =C8*D8*E8 -> 894.84 | G8: =F8 -> 894.84 | H8: =F8 -> 894.84 | I8: =G8/(220) -> 4.0674545 | J8: =0.8*H8 -> 715.872 | K8: =1.25*L8 -> 1.7014755 | L8: =H8/(1.73*380*1) -> 1.3611804
A9: C-3 | B9: CIRCUITO DE BOMBA 3 | C9: =745.7*1.5 -> 1118.55 | D9: 1 | E9: 0.8 | F9: =C9*D9*E9 -> 894.84 | G9: =F9 -> 894.84 | H9: =F9 -> 894.84 | I9: =G9/(220) -> 4.0674545 | J9: =0.8*H9 -> 715.872 | K9: =1.25*L9 -> 1.7014755 | L9: =H9/(1.73*380*1) -> 1.3611804
A10: C-4 | B10: CIRCUITO DE BOMBA 4 | C10: =745.7*1.5 -> 1118.55 | D10: 1 | E10: 0.8 | F10: =C10*D10*E10 -> 894.84 | G10: =F10 -> 894.84 | H10: =F10 -> 894.84 | I10: =G10/(220) -> 4.0674545 | J10: =0.8*H10 -> 715.872 | K10: =1.25*L10 -> 1.7014755 | L10: =H10/(1.73*380*1) -> 1.3611804
A11: C-5 | B11: CIRCUITO DE BOMBA 5 | C11: =745.7*1.5 -> 1118.55 | D11: 1 | E11: 0.8 | F11: =C11*D11*E11 -> 894.84 | G11: =F11 -> 894.84 | H11: =F11 -> 894.84 | I11: =G11/(220) -> 4.0674545 | J11: =0.8*H11 -> 715.872 | K11: =1.25*L11 -> 1.7014755 | L11: =H11/(1.73*380*1) -> 1.3611804
A12: C-6 | B12: CIRCUITO DE BOMBA 6 | C12: 18642.5 | D12: 1 | E12: 0.8 | F12: =C12*D12*E12 -> 14914 | G12: =F12 -> 14914 | H12: =F12 -> 14914 | I12: =G12/(220) -> 67.790909 | J12: =0.8*H12 -> 11931.2 | K12: =1.25*L12 -> 28.357925 | L12: =H12/(1.73*380*1) -> 22.68634
A13: C-7 | B13: CIRCUITO DE LUMINARIA EXTERIOR TIPO ISLA | C13: 32 | D13: 8 | E13: 1 | F13: =C13*D13*E13 -> 256 | G13: =F13 -> 256 | H13: =F13 -> 256 | I13: =G13/(220) -> 1.1636364 | J13: =1*H13 -> 256 | K13: =1.25*L13 -> 1.4545455 | L13: =H13/(1*220*1) -> 1.1636364
A14: C-8 | B14: CIRCUITO DE LUMINARIA EXTERIOR | C14: 16 | D14: 28 | E14: 1 | F14: =C14*D14*E14 -> 448 | G14: =F14 -> 448 | H14: =F14 -> 448 | I14: =G14/(220) -> 2.0363636 | J14: =1*H14 -> 448 | K14: =1.25*L14 -> 2.5454545 | L14: =H14/(1*220*1) -> 2.0363636
A15: C-9 | B15: CIRCUITO DE LUMINARIA EXTERIOR | C15: 16 | D15: 30 | E15: 1 | F15: =C15*D15*E15 -> 480 | G15: =F15 -> 480 | H15: =F15 -> 480 | I15: =G15/(220) -> 2.1818182 | J15: =1*H15 -> 480 | K15: =1.25*L15 -> 2.7272727 | L15: =H15/(1*220*1) -> 2.1818182
A16: C-1 | B16: TABLERO DE DISTRIBUCION 1 | H16: =SUM(H17:H30) -> 14779 | I16: =H16/(1.73*380*0.9) -> 24.978873 | J16: =0.8*H16 -> 11823.2 | K16: =1.25*L16 -> 28.101232 | L16: =H16/(1.73*380*1) -> 22.480986
A17: C-1 | B17: CIRCUITO TOMACORRIENTES | C17: 350 | D17: 9 | E17: 0.8 | F17: =C17*D17*E17 -> 2520 | G17: =F17 -> 2520 | H17: =F17 -> 2520 | I17: =G17/(220) -> 11.454545 | J17: =1*H17 -> 2520 | K17: =1.25*L17 -> 14.318182 | L17: =H17/(1*220*1) -> 11.454545
A18: C-2 | B18: CIRCUITO TOMACORRIENTES | C18: 350 | D18: 9 | E18: 0.8 | F18: =C18*D18*E18 -> 2520 | G18: =F18 -> 2520 | H18: =F18 -> 2520 | I18: =G18/(220) -> 11.454545 | J18: =1*H18 -> 2520 | K18: =1.25*L18 -> 14.318182 | L18: =H18/(1*220*1) -> 11.454545
A19: C-3 | B19: CIRCUITO TOMACORRIENTES | C19: 350 | D19: 9 | E19: 0.8 | F19: =C19*D19*E19 -> 2520 | G19: =F19 -> 2520 | H19: =F19 -> 2520 | I19: =G19/(220) -> 11.454545 | J19: =1*H19 -> 2520 | K19: =1.25*L19 -> 14.318182 | L19: =H19/(1*220*1) -> 11.454545
A20: C-4 | B20: CIRCUITO TOMACORRIENTES | C20: 350 | D20: 7 | E20: 0.8 | F20: =C20*D20*E20 -> 1960 | G20: =F20 -> 1960 | H20: =F20 -> 1960 | I20: =G20/(220) -> 8.9090909 | J20: =1*H20 -> 1960 | K20: =1.25*L20 -> 11.136364 | L20: =H20/(1*220*1) -> 8.9090909
A21: C-5 | B21: CIRCUITO TOMACORRIENTES Y FLUXOMETRO | C21: 50 | D21: 13 | E21: 0.8 | F21: =C21*D21*E21 -> 520 | G21: =F21 -> 520 | H21: =F21 -> 520 | I21: =G21/(220) -> 2.3636364 | J21: =1*H21 -> 520 | K21: =1.25*L21 -> 2.9545455 | L21: =H21/(1*220*1) -> 2.3636364
A22: C-6 | B22: CIRCUITO DE LUMINARIAS TIPO PANEL | C22: 42 | D22: 15 | E22: 1 | F22: =C22*D22*E22 -> 630 | G22: =F22 -> 630 | H22: =F22 -> 630 | I22: =G22/(220) -> 2.8636364 | J22: =1*H22 -> 630 | K22: =1.25*L22 -> 3.5795455 | L22: =H22/(1*220*1) -> 2.8636364
A23: C-7 | B23: CIRCUITO DE LUMINARIAS TIPO PANEL | C23: 47 | D23: 16 | E23: 1 | F23: =C23*D23*E23 -> 752 | G23: =F23 -> 752 | H23: =F23 -> 752 | I23: =G23/(220) -> 3.4181818 | J23: =1*H23 -> 752 | K23: =1.25*L23 -> 4.2727273 | L23: =H23/(1*220*1) -> 3.4181818
A24: C-8 | B24: CIRCUITO DE LUMINARIAS TIPO DOWNLIGHT, PANEL | C24: 21 | D24: 22 | E24: 1 | F24: =C24*D24*E24 -> 462 | G24: =F24 -> 462 | H24: =F24 -> 462 | I24: =G24/(220) -> 2.1 | J24: =1*H24 -> 462 | K24: =1.25*L24 -> 2.625 | L24: =H24/(1*220*1) -> 2.1
A25: C-9 | B25: CIRCUITO DE LUMINARIAS TIPO DOWNLIGHT | C25: 13 | D25: 12 | E25: 1 | F25: =C25*D25*E25 -> 156 | G25: =F25 -> 156 | H25: =F25 -> 156 | I25: =G25/(220) -> 0.70909091 | J25: =1*H25 -> 156 | K25: =1.25*L25 -> 0.88636364 | L25: =H25/(1*220*1) -> 0.70909091
A26: C-10 | B26: CIRCUITO DE LUMINARIAS | C26: 22.5 | D26: 22 | E26: 1 | F26: =C26*D26*E26 -> 495 | G26: =F26 -> 495 | H26: =F26 -> 495 | I26: =G26/(220) -> 2.25 | J26: =1*H26 -> 495 | K26: =1.25*L26 -> 2.8125 | L26: =H26/(1*220*1) -> 2.25
A27: C-11 | B27: CIRCUITO DE LUMINARIAS | C27: 22.5 | D27: 18 | E27: 1 | F27: =C27*D27*E27 -> 405 | G27: =F27 -> 405 | H27: =F27 -> 405 | I27: =G27/(220) -> 1.8409091 | J27: =1*H27 -> 405 | K27: =1.25*L27 -> 2.3011364 | L27: =H27/(1*220*1) -> 1.8409091
A28: C-12 | B28: CIRCUITO DE LUMINARIAS | C28: 42 | D28: 12 | E28: 1 | F28: =C28*D28*E28 -> 504 | G28: =F28 -> 504 | H28: =F28 -> 504 | I28: =G28/(220) -> 2.2909091 | J28: =1*H28 -> 504 | K28: =1.25*L28 -> 2.8636364 | L28: =H28/(1*220*1) -> 2.2909091
... A30: C-14 | B30: CIRCUITO DE LUMINARIAS | C30: 42 | D30: 15 | E30: 1 | F30: =C30*D30*E30 -> 630 | G30: =F30 -> 630 | H30: =F30 -> 630 | I30: =G30/(220) -> 2.8636364 | J30: =1*H30 -> 630 | K30: =1.25*L30 -> 3.5795455 | L30: =H30/(1*220*1) -> 2.8636364
A31: C-2 | B31: TABLERO DE DISTRIBUCION 2 | H31: =SUM(H32:H39) -> 17709 | I31: =H31/(1.73*380*0.9) -> 29.931041 | J31: =0.8*H31 -> 14167.2 | K31: =1.25*L31 -> 33.672422 | L31: =H31/(1.73*380*1) -> 26.937937
A32: C-1 | B32: CIRCUITO TOMACORRIENTES | C32: 350 | D32: 8 | E32: 0.8 | F32: =C32*D32*E32 -> 2240 | G32: =F32 -> 2240 | H32: =F32 -> 2240 | I32: =G32/(220) -> 10.181818 | J32: =1*H32 -> 2240 | K32: =1.25*L32 -> 12.727273 | L32: =H32/(1*220) -> 10.181818
A33: C-2 | B33: CIRCUITO TOMACORRIENTES | C33: 350 | D33: 10 | E33: 0.8 | F33: =C33*D33*E33 -> 2800 | G33: =F33 -> 2800 | H33: =F33 -> 2800 | I33: =G33/(220) -> 12.727273 | J33: =1*H33 -> 2800 | K33: =1.25*L33 -> 15.909091 | L33: =H33/(1*220) -> 12.727273
A34: C-3 | B34: CIRCUITO TOMACORRIENTES | C34: 350 | D34: 10 | E34: 0.8 | F34: =C34*D34*E34 -> 2800 | G34: =F34 -> 2800 | H34: =F34 -> 2800 | I34: =G34/(220) -> 12.727273 | J34: =1*H34 -> 2800 | K34: =1.25*L34 -> 15.909091 | L34: =H34/(1*220) -> 12.727273
A35: C-4 | B35: CIRCUITO TOMACORRIENTES | C35: 350 | D35: 12 | E35: 0.8 | F35: =C35*D35*E35 -> 3360 | G35: =F35 -> 3360 | H35: =F35 -> 3360 | I35: =G35/(220) -> 15.272727 | J35: =1*H35 -> 3360 | K35: =1.25*L35 -> 19.090909 | L35: =H35/(1*220) -> 15.272727
A36: C-5 | B36: CIRCUITO TOMACORRIENTES | C36: 350 | D36: 12 | E36: 0.8 | F36: =C36*D36*E36 -> 3360 | G36: =F36 -> 3360 | H36: =F36 -> 3360 | I36: =G36/(220) -> 15.272727 | J36: =1*H36 -> 3360 | K36: =1.25*L36 -> 19.090909 | L36: =H36/(1*220) -> 15.272727
A37: C-6 | B37: CIRCUITO DE LUMINARIAS TIPO PANEL | C37: 47 | D37: 21 | E37: 1 | F37: =C37*D37*E37 -> 987 | G37: =F37 -> 987 | H37: =F37 -> 987 | I37: =G37/(220) -> 4.4863636 | J37: =1*H37 -> 987 | K37: =1.25*L37 -> 5.6079545 | L37: =H37/(1*220) -> 4.4863636
A38: C-7 | B38: CIRCUITO DE LUMINARIAS SUSPENDIDO | C38: 47 | D38: 19 | E38: 1 | F38: =C38*D38*E38 -> 893 | G38: =F38 -> 893 | H38: =F38 -> 893 | I38: =G38/(220) -> 4.0590909 | J38: =1*H38 -> 893 | K38: =1.25*L38 -> 5.0738636 | L38: =H38/(1*220) -> 4.0590909
A39: C-8 | B39: CIRCUITO DE LUMINARIAS SUSPENDIDO | C39: 47 | D39: 27 | E39: 1 | F39: =C39*D39*E39 -> 1269 | G39: =F39 -> 1269 | H39: =F39 -> 1269 | I39: =G39/(220) -> 5.7681818 | J39: =1*H39 -> 1269 | K39: =1.25*L39 -> 7.2102273 | L39: =H39/(1*220) -> 5.7681818
A40: C-3 | B40: TABLERO DE DISTRIBUCION 3 | H40: =SUM(H41:H47) -> 10816 | I40: =H40/(1.73*380*0.9) -> 18.280769 | J40: =0.8*H40 -> 8652.8 | K40: =1.25*L40 -> 20.565866 | L40: =H40/(1.73*380*1) -> 16.452692
A41: C-1 | B41: CIRCUITO TOMACORRIENTES | C41: 350 | D41: 12 | E41: 0.8 | F41: =C41*D41*E41 -> 3360 | G41: =F41 -> 3360 | H41: =F41 -> 3360 | I41: =G41/(220) -> 15.272727 | J41: =1*H41 -> 3360 | K41: =1.25*L41 -> 19.090909 | L41: =H41/(1*220*1) -> 15.272727
...

Sheet CALCULO POR CIRCUITOS
A1: SUB TABLERO GENERAL
A2: CIRCUITO 1
A3: BOMBA PRMER NIVEL
A4: 1.- Cálculo por capacidad térmica
C5: donde:
C6: In: corriente nominal
C7: W:potencia instalada
C8: V: tension
C9: cos&: foctor de potencia
B11: In= | C11: ='CUADRO DE CARGAS'!L7 -> 2.7116364 | D11: Amp | E11: Buscar en la tabla
B12: Id= | C12: =1.25*C11 -> 3.3895455 | D12: Amp | E12: según tabla
B13: S= | C13: 6 | D13: mm2
A14: considerando: La longitud mas alejada
B15: L= | C15: 20 | D15: m
A16: 2.- calculo por caida de tension
A19: donde:
C20: Rho= resistividad del cobre | E20: 0.018
C21: R= | D21: =E20*C15/C13 -> 0.06
A23: Por lo tanto:
B25: =1*C12*D21 -> 0.20337273 | C25: menor a 5.5v | D25: si cumple
A27: CIRCUITO 2
A28: BOMBA SEGUNDO NIVEL
A29: 1.- Cálculo por capacidad térmica
C30: donde:
C31: In: corriente nominal
C32: W:potencia instalada
C33: V: tension
C34: cos&: foctor de potencia
B36: In= | C36: ='CUADRO DE CARGAS'!L8 -> 1.3611804 | D36: Amp | E36: Buscar en la tabla
B37: Id= | C37: =1.25*C36 -> 1.7014755 | D37: Amp | E37: según tabla
B38: S= | C38: 6 | D38: mm2
A39: considerando: La longitud mas alejada | C39: }
B40: L= | C40: 20 | D40: m
A41: 2.- calculo por caida de tension
A44: donde:
C45: Rho= resistividad del cobre | E45: 0.018
C46: R= | D46: =E45*C40/C38 -> 0.06
A48: Por lo tanto:
B50: =1.732*C37*D46*0.9 -> 0.1591356 | C50: menor a 5.5v | D50: si cumple
A52: CIRCUITO 3
...

Sheet CALCULOS  TAB. DIS.
A2: SUBTABLERO DE DISTRIBUCION A
A3: TABLERO DE DISTRIBUCION 1
A4: 1.- Cálculo por capacidad térmica
C5: donde:
C6: In: corriente nominal
C7: W:potencia instalada
C8: V: tension
C9: cos&: foctor de potencia
B11: In= | C11: ='CUADRO DE CARGAS'!L16 -> 22.480986 | D11: Amp | E11: Buscar en la tabla
B12: Id= | C12: =1.25*C11 -> 28.101232 | D12: Amp | E12: según tabla
B13: S= | C13: 10 | D13: mm2
A14: considerando: La longitud mas alejada
B15: L= | C15: 25 | D15: m
A16: 2.- calculo por caida de tension
A19: donde:
C20: Rho= resistividad del cobre | E20: 0.018
C21: R= | D21: =E20*C15/C13 -> 0.045
A23: Por lo tanto:
B25: =1.732*C12*D21*0.9 -> 1.971189 | C25: menor a 5.5v | D25: si cumple
A27: TABLERO DE DISTRIBUCION 2
A28: 1.- Cálculo por capacidad térmica
C29: donde:
C30: In: corriente nominal
C31: W:potencia instalada
C32: V: tension
C33: cos&: foctor de potencia
B35: In= | C35: ='CUADRO DE CARGAS'!L31 -> 26.937937 | D35: Amp | E35: Buscar en la tabla
B36: Id= | C36: =1.25*C35 -> 33.672422 | D36: Amp | E36: según tabla
B37: S= | C37: 10 | D37: mm2
A38: considerando: La longitud mas alejada
B39: L= | C39: 34.8 | D39: m
A40: 2.- calculo por caida de tension
A43: donde:
C44: Rho= resistividad del cobre | E44: 0.018
C45: R= | D45: =E44*C39/C37 -> 0.06264
A47: Por lo tanto:
B49: =1.732*C36*D45*0.9 -> 3.2878841 | C49: menor a 5.5v | D49: si cumple
A51: TABLERO DE DISTRIBUCION 3
A52: 1.- Cálculo por capacidad térmica
C53: donde:
...

Sheet CALCULO TAB. GEN. Y SUB. TAB
A1: TABLERO GENERAL
A2: 1.- Cálculo por capacidad térmica
C3: donde:
C4: In: corriente nominal
C5: W:potencia instalada
C6: V: tension
C7: cos&: foctor de potencia
B9: In= | C9: ='CUADRO DE CARGAS'!L5 -> 259.85689 | D9: Amp | E9: Buscar en la tabla
B10: Id= | C10: =1.25*C9 -> 324.82111 | D10: Amp | E10: según tabla
B11: S= | C11: 95 | D11: mm2
A12: considerando: La longitud mas alejada
B13: L= | C13: 30 | D13: m
A14: 2.- calculo por caida de tension
A17: donde:
C18: Rho= resistividad del cobre | E18: 0.018
C19: R= | D19: =E18*C13/C11 -> 0.0056842105
A21: Por lo tanto:
B23: =1.732*C10*D19*0.9 -> 2.8780929 | C23: menor a 5.5v | D23: si cumple
A26: SUBTABLERO DE GENERAL A
A27: 1.- Cálculo por capacidad térmica
C28: donde:
C29: In: corriente nominal
C30: W:potencia instalada
C31: V: tension
C32: cos&: foctor de potencia
B34: In= | C34: ='CUADRO DE CARGAS'!L6 -> 30.83955 | D34: Amp | E34: Buscar en la tabla
B35: Id= | C35: =1.25*C34 -> 38.549437 | D35: Amp | E35: según tabla
B36: S= | C36: 10 | D36: mm2
A37: considerando: La longitud mas alejada
B38: L= | C38: 7 | D38: m
A39: 2.- calculo por caida de tension
A42: donde:
C43: Rho= resistividad del cobre | E43: 0.018
C44: R= | D44: =E43*C38/C36 -> 0.0126
A46: Por lo tanto:
B48: =1.732*C35*D44*0.9 -> 0.75714487 | C48: menor a 5.5v | D48: si cumple
